Workbook

Sheet ตารางเวร
A1: 📋 ตารางเวรพยาบาล | D1: วิธีกรอก: พิมพ์ D หรือ DE ในช่องวันที่เข้าเวร · เว้นว่าง = ไม่เข้าเวร (ขึ้นเขียวเอง)
A2: เดือน | B2: 8 | D2: เติม * ท้ายรหัสถ้าคนนั้นอยู่ "ฝั่งขวา P1" วันนั้น เช่น DE* หรือ D* → ช่องจะกลายเป็นสีส้มให้เอง
A3: ปี พ.ศ. | B3: 2569 | D3: คอลัมน์ "ห้าม T" ใส่ x = คนนั้นจะไม่ถูกสุ่มลงช่อง T เด็ดขาด
A4: เลขสุ่ม | B4: 7 | D4: อยากได้ผลสุ่มฝั่งขวาแบบใหม่ → เปลี่ยน "เลขสุ่ม" เป็นเลขอื่น · พิมพ์เลขเดิมกลับ = ได้ตารางเดิมเป๊ะ
A5: (D) ฝั่งขวา | B5: x | D5: ช่อง "(D) ฝั่งขวา" มี x = ฝั่งขวาต่อท้าย (D) ด้วย · ลบ x ออก = ฝั่งขวาโชว์ชื่อเปล่า (ฝั่งซ้ายมี (D) เสมอ)
C6: =IF(1>DAY(EOMONTH(DATE('ตารางเวร'!$B$3-543,'ตารางเวร'!$B$2,1),0)),"",DATE('ตารางเวร'!$B$3-543,'ตารางเวร'!$B$2,1)) | D6: =IF(2>DAY(EOMONTH(DATE('ตารางเวร'!$B$3-543,'ตารางเวร'!$B$2,1),0)),"",DATE('ตารางเวร'!$B$3-543,'ตารางเวร'!$B$2,2)) | E6: =IF(3>DAY(EOMONTH(DATE('ตารางเวร'!$B$3-543,'ตารางเวร'!$B$2,1),0)),"",DATE('ตารางเวร'!$B$3-543,'ตารางเวร'!$B$2,3)) | F6: =IF(4>DAY(EOMONTH(DATE('ตารางเวร'!$B$3-543,'ตารางเวร'!$B$2,1),0)),"",DATE('ตารางเวร'!$B$3-543,'ตารางเวร'!$B$2,4)) | G6: =IF(5>DAY(EOMONTH(DATE('ตารางเวร'!$B$3-543,'ตารางเวร'!$B$2,1),0)),"",DATE('ตารางเวร'!$B$3-543,'ตารางเวร'!$B$2,5)) | H6: =IF(6>DAY(EOMONTH(DATE('ตารางเวร'!$B$3-543,'ตารางเวร'!$B$2,1),0)),"",DATE('ตารางเวร'!$B$3-543,'ตารางเวร'!$B$2,6)) | I6: =IF(7>DAY(EOMONTH(DATE('ตารางเวร'!$B$3-543,'ตารางเวร'!$B$2,1),0)),"",DATE('ตารางเวร'!$B$3-543,'ตารางเวร'!$B$2,7)) | J6: =IF(8>DAY(EOMONTH(DATE('ตารางเวร'!$B$3-543,'ตารางเวร'!$B$2,1),0)),"",DATE('ตารางเวร'!$B$3-543,'ตารางเวร'!$B$2,8)) | K6: =IF(9>DAY(EOMONTH(DATE('ตารางเวร'!$B$3-543,'ตารางเวร'!$B$2,1),0)),"",DATE('ตารางเวร'!$B$3-543,'ตารางเวร'!$B$2,9)) | L6: =IF(10>DAY(EOMONTH(DATE('ตารางเวร'!$B$3-543,'ตารางเวร'!$B$2,1),0)),"",DATE('ตารางเวร'!$B$3-543,'ตารางเวร'!$B$2,10)) | M6: =IF(11>DAY(EOMONTH(DATE('ตารางเวร'!$B$3-543,'ตารางเวร'!$B$2,1),0)),"",DATE('ตารางเวร'!$B$3-543,'ตารางเวร'!$B$2,11)) | N6: =IF(12>DAY(EOMONTH(DATE('ตารางเวร'!$B$3-543,'ตารางเวร'!$B$2,1),0)),"",DATE('ตารางเวร'!$B$3-543,'ตารางเวร'!$B$2,12)) | O6: =IF(13>DAY(EOMONTH(DATE('ตารางเวร'!$B$3-543,'ตารางเวร'!$B$2,1),0)),"",DATE('ตารางเวร'!$B$3-543,'ตารางเวร'!$B$2,13)) | P6: =IF(14>DAY(EOMONTH(DATE('ตารางเวร'!$B$3-543,'ตารางเวร'!$B$2,1),0)),"",DATE('ตารางเวร'!$B$3-543,'ตารางเวร'!$B$2,14)) | Q6: =IF(15>DAY(EOMONTH(DATE('ตารางเวร'!$B$3-543,'ตารางเวร'!$B$2,1),0)),"",DATE('ตารางเวร'!$B$3-543,'ตารางเวร'!$B$2,15)) | R6: =IF(16>DAY(EOMONTH(DATE('ตารางเวร'!$B$3-543,'ตารางเวร'!$B$2,1),0)),"",DATE('ตารางเวร'!$B$3-543,'ตารางเวร'!$B$2,16)) | S6: =IF(17>DAY(EOMONTH(DATE('ตารางเวร'!$B$3-543,'ตารางเวร'!$B$2,1),0)),"",DATE('ตารางเวร'!$B$3-543,'ตารางเวร'!$B$2,17)) | T6: =IF(18>DAY(EOMONTH(DATE('ตารางเวร'!$B$3-543,'ตารางเวร'!$B$2,1),0)),"",DATE('ตารางเวร'!$B$3-543,'ตารางเวร'!$B$2,18)) | U6: =IF(19>DAY(EOMONTH(DATE('ตารางเวร'!$B$3-543,'ตารางเวร'!$B$2,1),0)),"",DATE('ตารางเวร'!$B$3-543,'ตารางเวร'!$B$2,19)) | V6: =IF(20>DAY(EOMONTH(DATE('ตารางเวร'!$B$3-543,'ตารางเวร'!$B$2,1),0)),"",DATE('ตารางเวร'!$B$3-543,'ตารางเวร'!$B$2,20)) | W6: =IF(21>DAY(EOMONTH(DATE('ตารางเวร'!$B$3-543,'ตารางเวร'!$B$2,1),0)),"",DATE('ตารางเวร'!$B$3-543,'ตารางเวร'!$B$2,21)) | X6: =IF(22>DAY(EOMONTH(DATE('ตารางเวร'!$B$3-543,'ตารางเวร'!$B$2,1),0)),"",DATE('ตารางเวร'!$B$3-543,'ตารางเวร'!$B$2,22)) | Y6: =IF(23>DAY(EOMONTH(DATE('ตารางเวร'!$B$3-543,'ตารางเวร'!$B$2,1),0)),"",DATE('ตารางเวร'!$B$3-543,'ตารางเวร'!$B$2,23)) | Z6: =IF(24>DAY(EOMONTH(DATE('ตารางเวร'!$B$3-543,'ตารางเวร'!$B$2,1),0)),"",DATE('ตารางเวร'!$B$3-543,'ตารางเวร'!$B$2,24)) | AA6: =IF(25>DAY(EOMONTH(DATE('ตารางเวร'!$B$3-543,'ตารางเวร'!$B$2,1),0)),"",DATE('ตารางเวร'!$B$3-543,'ตารางเวร'!$B$2,25)) | AB6: =IF(26>DAY(EOMONTH(DATE('ตารางเวร'!$B$3-543,'ตารางเวร'!$B$2,1),0)),"",DATE('ตารางเวร'!$B$3-543,'ตารางเวร'!$B$2,26)) | AC6: =IF(27>DAY(EOMONTH(DATE('ตารางเวร'!$B$3-543,'ตารางเวร'!$B$2,1),0)),"",DATE('ตารางเวร'!$B$3-543,'ตารางเวร'!$B$2,27)) | AD6: =IF(28>DAY(EOMONTH(DATE('ตารางเวร'!$B$3-543,'ตารางเวร'!$B$2,1),0)),"",DATE('ตารางเวร'!$B$3-543,'ตารางเวร'!$B$2,28)) | AE6: =IF(29>DAY(EOMONTH(DATE('ตารางเวร'!$B$3-543,'ตารางเวร'!$B$2,1),0)),"",DATE('ตารางเวร'!$B$3-543,'ตารางเวร'!$B$2,29)) | AF6: =IF(30>DAY(EOMONTH(DATE('ตารางเวร'!$B$3-543,'ตารางเวร'!$B$2,1),0)),"",DATE('ตารางเวร'!$B$3-543,'ตารางเวร'!$B$2,30)) | AG6: =IF(31>DAY(EOMONTH(DATE('ตารางเวร'!$B$3-543,'ตารางเวร'!$B$2,1),0)),"",DATE('ตารางเวร'!$B$3-543,'ตารางเวร'!$B$2,31))
C7: =IF(C6="",0,IF(OR(WEEKDAY(C6,2)>5,COUNTIF($AJ$10:$AJ$22,1)>0),1,0)) | D7: =IF(D6="",0,IF(OR(WEEKDAY(D6,2)>5,COUNTIF($AJ$10:$AJ$22,2)>0),1,0)) | E7: =IF(E6="",0,IF(OR(WEEKDAY(E6,2)>5,COUNTIF($AJ$10:$AJ$22,3)>0),1,0)) | F7: =IF(F6="",0,IF(OR(WEEKDAY(F6,2)>5,COUNTIF($AJ$10:$AJ$22,4)>0),1,0)) | G7: =IF(G6="",0,IF(OR(WEEKDAY(G6,2)>5,COUNTIF($AJ$10:$AJ$22,5)>0),1,0)) | H7: =IF(H6="",0,IF(OR(WEEKDAY(H6,2)>5,COUNTIF($AJ$10:$AJ$22,6)>0),1,0)) | I7: =IF(I6="",0,IF(OR(WEEKDAY(I6,2)>5,COUNTIF($AJ$10:$AJ$22,7)>0),1,0)) | J7: =IF(J6="",0,IF(OR(WEEKDAY(J6,2)>5,COUNTIF($AJ$10:$AJ$22,8)>0),1,0)) | K7: =IF(K6="",0,IF(OR(WEEKDAY(K6,2)>5,COUNTIF($AJ$10:$AJ$22,9)>0),1,0)) | L7: =IF(L6="",0,IF(OR(WEEKDAY(L6,2)>5,COUNTIF($AJ$10:$AJ$22,10)>0),1,0)) | M7: =IF(M6="",0,IF(OR(WEEKDAY(M6,2)>5,COUNTIF($AJ$10:$AJ$22,11)>0),1,0)) | N7: =IF(N6="",0,IF(OR(WEEKDAY(N6,2)>5,COUNTIF($AJ$10:$AJ$22,12)>0),1,0)) | O7: =IF(O6="",0,IF(OR(WEEKDAY(O6,2)>5,COUNTIF($AJ$10:$AJ$22,13)>0),1,0)) | P7: =IF(P6="",0,IF(OR(WEEKDAY(P6,2)>5,COUNTIF($AJ$10:$AJ$22,14)>0),1,0)) | Q7: =IF(Q6="",0,IF(OR(WEEKDAY(Q6,2)>5,COUNTIF($AJ$10:$AJ$22,15)>0),1,0)) | R7: =IF(R6="",0,IF(OR(WEEKDAY(R6,2)>5,COUNTIF($AJ$10:$AJ$22,16)>0),1,0)) | S7: =IF(S6="",0,IF(OR(WEEKDAY(S6,2)>5,COUNTIF($AJ$10:$AJ$22,17)>0),1,0)) | T7: =IF(T6="",0,IF(OR(WEEKDAY(T6,2)>5,COUNTIF($AJ$10:$AJ$22,18)>0),1,0)) | U7: =IF(U6="",0,IF(OR(WEEKDAY(U6,2)>5,COUNTIF($AJ$10:$AJ$22,19)>0),1,0)) | V7: =IF(V6="",0,IF(OR(WEEKDAY(V6,2)>5,COUNTIF($AJ$10:$AJ$22,20)>0),1,0)) | W7: =IF(W6="",0,IF(OR(WEEKDAY(W6,2)>5,COUNTIF($AJ$10:$AJ$22,21)>0),1,0)) | X7: =IF(X6="",0,IF(OR(WEEKDAY(X6,2)>5,COUNTIF($AJ$10:$AJ$22,22)>0),1,0)) | Y7: =IF(Y6="",0,IF(OR(WEEKDAY(Y6,2)>5,COUNTIF($AJ$10:$AJ$22,23)>0),1,0)) | Z7: =IF(Z6="",0,IF(OR(WEEKDAY(Z6,2)>5,COUNTIF($AJ$10:$AJ$22,24)>0),1,0)) | AA7: =IF(AA6="",0,IF(OR(WEEKDAY(AA6,2)>5,COUNTIF($AJ$10:$AJ$22,25)>0),1,0)) | AB7: =IF(AB6="",0,IF(OR(WEEKDAY(AB6,2)>5,COUNTIF($AJ$10:$AJ$22,26)>0),1,0)) | AC7: =IF(AC6="",0,IF(OR(WEEKDAY(AC6,2)>5,COUNTIF($AJ$10:$AJ$22,27)>0),1,0)) | AD7: =IF(AD6="",0,IF(OR(WEEKDAY(AD6,2)>5,COUNTIF($AJ$10:$AJ$22,28)>0),1,0)) | AE7: =IF(AE6="",0,IF(OR(WEEKDAY(AE6,2)>5,COUNTIF($AJ$10:$AJ$22,29)>0),1,0)) | AF7: =IF(AF6="",0,IF(OR(WEEKDAY(AF6,2)>5,COUNTIF($AJ$10:$AJ$22,30)>0),1,0)) | AG7: =IF(AG6="",0,IF(OR(WEEKDAY(AG6,2)>5,COUNTIF($AJ$10:$AJ$22,31)>0),1,0))
A8: ชื่อ-สกุล | B8: ห้าม T | C8: =IF(C6="","",1) | D8: =IF(D6="","",2) | E8: =IF(E6="","",3) | F8: =IF(F6="","",4) | G8: =IF(G6="","",5) | H8: =IF(H6="","",6) | I8: =IF(I6="","",7) | J8: =IF(J6="","",8) | K8: =IF(K6="","",9) | L8: =IF(L6="","",10) | M8: =IF(M6="","",11) | N8: =IF(N6="","",12) | O8: =IF(O6="","",13) | P8: =IF(P6="","",14) | Q8: =IF(Q6="","",15) | R8: =IF(R6="","",16) | S8: =IF(S6="","",17) | T8: =IF(T6="","",18) | U8: =IF(U6="","",19) | V8: =IF(V6="","",20) | W8: =IF(W6="","",21) | X8: =IF(X6="","",22) | Y8: =IF(Y6="","",23) | Z8: =IF(Z6="","",24) | AA8: =IF(AA6="","",25) | AB8: =IF(AB6="","",26) | AC8: =IF(AC6="","",27) | AD8: =IF(AD6="","",28) | AE8: =IF(AE6="","",29) | AF8: =IF(AF6="","",30) | AG8: =IF(AG6="","",31) | AJ8: วันหยุด | AL8: ⚙️ ตั้งค่า
C9: =IF(C6="","",CHOOSE(WEEKDAY(C6),"อา","จ","อ","พ","พฤ","ศ","ส")) | D9: =IF(D6="","",CHOOSE(WEEKDAY(D6),"อา","จ","อ","พ","พฤ","ศ","ส")) | E9: =IF(E6="","",CHOOSE(WEEKDAY(E6),"อา","จ","อ","พ","พฤ","ศ","ส")) | F9: =IF(F6="","",CHOOSE(WEEKDAY(F6),"อา","จ","อ","พ","พฤ","ศ","ส")) | G9: =IF(G6="","",CHOOSE(WEEKDAY(G6),"อา","จ","อ","พ","พฤ","ศ","ส")) | H9: =IF(H6="","",CHOOSE(WEEKDAY(H6),"อา","จ","อ","พ","พฤ","ศ","ส")) | I9: =IF(I6="","",CHOOSE(WEEKDAY(I6),"อา","จ","อ","พ","พฤ","ศ","ส")) | J9: =IF(J6="","",CHOOSE(WEEKDAY(J6),"อา","จ","อ","พ","พฤ","ศ","ส")) | ... AG9: =IF(AG6="","",CHOOSE(WEEKDAY(AG6),"อา","จ","อ","พ","พฤ","ศ","ส")) | AJ9: (เลขวันที่)
A10: สมหญิง | AJ10: 12 | AO10: จันทร์
A11: วราภรณ์ | AL11: ฝั่ง P1 หยุดวัน | AM11: พฤหัสบดี | AO11: อังคาร
A12: ประไพ* | AO12: พุธ
A13: นภาพร | AL13: ชื่อช่องฝั่ง P1 | AO13: พฤหัสบดี
A14: กัลยา | AL14: ช่องที่ 1 | AM14: T | AO14: ศุกร์
A15: ศิริพร | AL15: ช่องที่ 2 | AM15: ซ1 | AO15: เสาร์
A16: ธนากร | AL16: ช่องที่ 3 | AM16: ซ2 | AO16: อาทิตย์
A17: มาลี | AL17: ช่องที่ 4 | AM17: ก | AO17: (ไม่หยุด)
A18: รุ่งทิพย์ | B18: x
A19: ปิยะดา
A20: จันทร์เพ็ญ | B20: x
A21: สุดารัตน์

Sheet คำนวณ
A1: ชีตช่วยคำนวณ — ห้ามแก้ด้วยมือ
A2: วันที่
A3: 1 | B3: =IF(1>DAY(EOMONTH(DATE('ตารางเวร'!$B$3-543,'ตารางเวร'!$B$2,1),0)),0,1) | C3: =IF($B3=0,"",IFERROR(TRIM(INDEX('ตารางเวร'!$C$10:$AG$29,1,$A3)),"")) | D3: =IF($B3=0,"",IFERROR(TRIM(INDEX('ตารางเวร'!$C$10:$AG$29,2,$A3)),"")) | E3: =IF($B3=0,"",IFERROR(TRIM(INDEX('ตารางเวร'!$C$10:$AG$29,3,$A3)),"")) | F3: =IF($B3=0,"",IFERROR(TRIM(INDEX('ตารางเวร'!$C$10:$AG$29,4,$A3)),"")) | G3: =IF($B3=0,"",IFERROR(TRIM(INDEX('ตารางเวร'!$C$10:$AG$29,5,$A3)),"")) | H3: =IF($B3=0,"",IFERROR(TRIM(INDEX('ตารางเวร'!$C$10:$AG$29,6,$A3)),"")) | I3: =IF($B3=0,"",IFERROR(TRIM(INDEX('ตารางเวร'!$C$10:$AG$29,7,$A3)),"")) | J3: =IF($B3=0,"",IFERROR(TRIM(INDEX('ตารางเวร'!$C$10:$AG$29,8,$A3)),"")) | K3: =IF($B3=0,"",IFERROR(TRIM(INDEX('ตารางเวร'!$C$10:$AG$29,9,$A3)),"")) | L3: =IF($B3=0,"",IFERROR(TRIM(INDEX('ตารางเวร'!$C$10:$AG$29,10,$A3)),"")) | M3: =IF($B3=0,"",IFERROR(TRIM(INDEX('ตารางเวร'!$C$10:$AG$29,11,$A3)),"")) | N3: =IF($B3=0,"",IFERROR(TRIM(INDEX('ตารางเวร'!$C$10:$AG$29,12,$A3)),"")) | O3: =IF($B3=0,"",IFERROR(TRIM(INDEX('ตารางเวร'!$C$10:$AG$29,13,$A3)),"")) | P3: =IF($B3=0,"",IFERROR(TRIM(INDEX('ตารางเวร'!$C$10:$AG$29,14,$A3)),"")) | Q3: =IF($B3=0,"",IFERROR(TRIM(INDEX('ตารางเวร'!$C$10:$AG$29,15,$A3)),"")) | R3: =IF($B3=0,"",IFERROR(TRIM(INDEX('ตารางเวร'!$C$10:$AG$29,16,$A3)),"")) | S3: =IF($B3=0,"",IFERROR(TRIM(INDEX('ตารางเวร'!$C$10:$AG$29,17,$A3)),"")) | T3: =IF($B3=0,"",IFERROR(TRIM(INDEX('ตารางเวร'!$C$10:$AG$29,18,$A3)),"")) | U3: =IF($B3=0,"",IFERROR(TRIM(INDEX('ตารางเวร'!$C$10:$AG$29,19,$A3)),"")) | V3: =IF($B3=0,"",IFERROR(TRIM(INDEX('ตารางเวร'!$C$10:$AG$29,20,$A3)),"")) | W3: =IF(AND($B3=1,C3<>"",ISNUMBER(FIND("*",C3))),MOD((MOD('ตารางเวร'!$B$4,9973)*7919+$A3*40289)*(1*104729+7919),99991)*100+1,999999999) | X3: =IF(AND($B3=1,D3<>"",ISNUMBER(FIND("*",D3))),MOD((MOD('ตารางเวร'!$B$4,9973)*7919+$A3*40289)*(2*104729+7919),99991)*100+2,999999999) | Y3: =IF(AND($B3=1,E3<>"",ISNUMBER(FIND("*",E3))),MOD((MOD('ตารางเวร'!$B$4,9973)*7919+$A3*40289)*(3*104729+7919),99991)*100+3,999999999) | Z3: =IF(AND($B3=1,F3<>"",ISNUMBER(FIND("*",F3))),MOD((MOD('ตารางเวร'!$B$4,9973)*7919+$A3*40289)*(4*104729+7919),99991)*100+4,999999999) | AA3: =IF(AND($B3=1,G3<>"",ISNUMBER(FIND("*",G3))),MOD((MOD('ตารางเวร'!$B$4,9973)*7919+$A3*40289)*(5*104729+7919),99991)*100+5,999999999) | AB3: =IF(AND($B3=1,H3<>"",ISNUMBER(FIND("*",H3))),MOD((MOD('ตารางเวร'!$B$4,9973)*7919+$A3*40289)*(6*104729+7919),99991)*100+6,999999999) | AC3: =IF(AND($B3=1,I3<>"",ISNUMBER(FIND("*",I3))),MOD((MOD('ตารางเวร'!$B$4,9973)*7919+$A3*40289)*(7*104729+7919),99991)*100+7,999999999) | AD3: =IF(AND($B3=1,J3<>"",ISNUMBER(FIND("*",J3))),MOD((MOD('ตารางเวร'!$B$4,9973)*7919+$A3*40289)*(8*104729+7919),99991)*100+8,999999999) | AE3: =IF(AND($B3=1,K3<>"",ISNUMBER(FIND("*",K3))),MOD((MOD('ตารางเวร'!$B$4,9973)*7919+$A3*40289)*(9*104729+7919),99991)*100+9,999999999) | AF3: =IF(AND($B3=1,L3<>"",ISNUMBER(FIND("*",L3))),MOD((MOD('ตารางเวร'!$B$4,9973)*7919+$A3*40289)*(10*104729+7919),99991)*100+10,999999999) | AG3: =IF(AND($B3=1,M3<>"",ISNUMBER(FIND("*",M3))),MOD((MOD('ตารางเวร'!$B$4,9973)*7919+$A3*40289)*(11*104729+7919),99991)*100+11,999999999) | AH3: =IF(AND($B3=1,N3<>"",ISNUMBER(FIND("*",N3))),MOD((MOD('ตารางเวร'!$B$4,9973)*7919+$A3*40289)*(12*104729+7919),99991)*100+12,999999999) | AI3: =IF(AND($B3=1,O3<>"",ISNUMBER(FIND("*",O3))),MOD((MOD('ตารางเวร'!$B$4,9973)*7919+$A3*40289)*(13*104729+7919),99991)*100+13,999999999) | AJ3: =IF(AND($B3=1,P3<>"",ISNUMBER(FIND("*",P3))),MOD((MOD('ตารางเวร'!$B$4,9973)*7919+$A3*40289)*(14*104729+7919),99991)*100+14,999999999) | AK3: =IF(AND($B3=1,Q3<>"",ISNUMBER(FIND("*",Q3))),MOD((MOD('ตารางเวร'!$B$4,9973)*7919+$A3*40289)*(15*104729+7919),99991)*100+15,999999999) | AL3: =IF(AND($B3=1,R3<>"",ISNUMBER(FIND("*",R3))),MOD((MOD('ตารางเวร'!$B$4,9973)*7919+$A3*40289)*(16*104729+7919),99991)*100+16,999999999) | AM3: =IF(AND($B3=1,S3<>"",ISNUMBER(FIND("*",S3))),MOD((MOD('ตารางเวร'!$B$4,9973)*7919+$A3*40289)*(17*104729+7919),99991)*100+17,999999999) | AN3: =IF(AND($B3=1,T3<>"",ISNUMBER(FIND("*",T3))),MOD((MOD('ตารางเวร'!$B$4,9973)*7919+$A3*40289)*(18*104729+7919),99991)*100+18,999999999) | AO3: =IF(AND($B3=1,U3<>"",ISNUMBER(FIND("*",U3))),MOD((MOD('ตารางเวร'!$B$4,9973)*7919+$A3*40289)*(19*104729+7919),99991)*100+19,999999999) | AP3: =IF(AND($B3=1,V3<>"",ISNUMBER(FIND("*",V3))),MOD((MOD('ตารางเวร'!$B$4,9973)*7919+$A3*40289)*(20*104729+7919),99991)*100+20,999999999) | AQ3: =IF(TRIM('ตารางเวร'!$B$10)<>"",999999999,W3) | AR3: =IF(TRIM('ตารางเวร'!$B$11)<>"",999999999,X3) | AS3: =IF(TRIM('ตารางเวร'!$B$12)<>"",999999999,Y3) | AT3: =IF(TRIM('ตารางเวร'!$B$13)<>"",999999999,Z3) | AU3: =IF(TRIM('ตารางเวร'!$B$14)<>"",999999999,AA3) | AV3: =IF(TRIM('ตารางเวร'!$B$15)<>"",999999999,AB3) | AW3: =IF(TRIM('ตารางเวร'!$B$16)<>"",999999999,AC3) | AX3: =IF(TRIM('ตารางเวร'!$B$17)<>"",999999999,AD3) | AY3: =IF(TRIM('ตารางเวร'!$B$18)<>"",999999999,AE3) | AZ3: =IF(TRIM('ตารางเวร'!$B$19)<>"",999999999,AF3) | BA3: =IF(TRIM('ตารางเวร'!$B$20)<>"",999999999,AG3) | BB3: =IF(TRIM('ตารางเวร'!$B$21)<>"",999999999,AH3) | BC3: =IF(TRIM('ตารางเวร'!$B$22)<>"",999999999,AI3) | BD3: =IF(TRIM('ตารางเวร'!$B$23)<>"",999999999,AJ3) | BE3: =IF(TRIM('ตารางเวร'!$B$24)<>"",999999999,AK3) | BF3: =IF(TRIM('ตารางเวร'!$B$25)<>"",999999999,AL3) | BG3: =IF(TRIM('ตารางเวร'!$B$26)<>"",999999999,AM3) | BH3: =IF(TRIM('ตารางเวร'!$B$27)<>"",999999999,AN3) | BI3: =IF(TRIM('ตารางเวร'!$B$28)<>"",999999999,AO3) | BJ3: =IF(TRIM('ตารางเวร'!$B$29)<>"",999999999,AP3) | BK3: =IF(AND($B3=1,C3<>"",NOT(ISNUMBER(FIND("*",C3)))),1,999999) | BL3: =IF(AND($B3=1,D3<>"",NOT(ISNUMBER(FIND("*",D3)))),2,999999) | BM3: =IF(AND($B3=1,E3<>"",NOT(ISNUMBER(FIND("*",E3)))),3,999999) | BN3: =IF(AND($B3=1,F3<>"",NOT(ISNUMBER(FIND("*",F3)))),4,999999) | BO3: =IF(AND($B3=1,G3<>"",NOT(ISNUMBER(FIND("*",G3)))),5,999999) | BP3: =IF(AND($B3=1,H3<>"",NOT(ISNUMBER(FIND("*",H3)))),6,999999) | BQ3: =IF(AND($B3=1,I3<>"",NOT(ISNUMBER(FIND("*",I3)))),7,999999) | BR3: =IF(AND($B3=1,J3<>"",NOT(ISNUMBER(FIND("*",J3)))),8,999999) | BS3: =IF(AND($B3=1,K3<>"",NOT(ISNUMBER(FIND("*",K3)))),9,999999) | BT3: =IF(AND($B3=1,L3<>"",NOT(ISNUMBER(FIND("*",L3)))),10,999999) | BU3: =IF(AND($B3=1,M3<>"",NOT(ISNUMBER(FIND("*",M3)))),11,999999) | BV3: =IF(AND($B3=1,N3<>"",NOT(ISNUMBER(FIND("*",N3)))),12,999999) | BW3: =IF(AND($B3=1,O3<>"",NOT(ISNUMBER(FIND("*",O3)))),13,999999) | BX3: =IF(AND($B3=1,P3<>"",NOT(ISNUMBER(FIND("*",P3)))),14,999999) | BY3: =IF(AND($B3=1,Q3<>"",NOT(ISNUMBER(FIND("*",Q3)))),15,999999) | BZ3: =IF(AND($B3=1,R3<>"",NOT(ISNUMBER(FIND("*",R3)))),16,999999) | CA3: =IF(AND($B3=1,S3<>"",NOT(ISNUMBER(FIND("*",S3)))),17,999999) | CB3: =IF(AND($B3=1,T3<>"",NOT(ISNUMBER(FIND("*",T3)))),18,999999) | CC3: =IF(AND($B3=1,U3<>"",NOT(ISNUMBER(FIND("*",U3)))),19,999999) | CD3: =IF(AND($B3=1,V3<>"",NOT(ISNUMBER(FIND("*",V3)))),20,999999) | CE3: =IF(MIN(AQ3:BJ3)>=999999999,0,MATCH(MIN(AQ3:BJ3),AQ3:BJ3,0)) | CF3: =IF($CE3=1,999999999,W3) | CG3: =IF($CE3=2,999999999,X3) | CH3: =IF($CE3=3,999999999,Y3) | CI3: =IF($CE3=4,999999999,Z3) | CJ3: =IF($CE3=5,999999999,AA3) | CK3: =IF($CE3=6,999999999,AB3) | CL3: =IF($CE3=7,999999999,AC3) | CM3: =IF($CE3=8,999999999,AD3) | CN3: =IF($CE3=9,999999999,AE3) | CO3: =IF($CE3=10,999999999,AF3) | CP3: =IF($CE3=11,999999999,AG3) | CQ3: =IF($CE3=12,999999999,AH3) | CR3: =IF($CE3=13,999999999,AI3) | CS3: =IF($CE3=14,999999999,AJ3) | CT3: =IF($CE3=15,999999999,AK3) | CU3: =IF($CE3=16,999999999,AL3) | CV3: =IF($CE3=17,999999999,AM3) | CW3: =IF($CE3=18,999999999,AN3) | CX3: =IF($CE3=19,999999999,AO3) | CY3: =IF($CE3=20,999999999,AP3) | CZ3: =COUNTIF(W3:AP3,"<999999999") | DA3: =COUNTIF(BK3:CD3,"<999999") | DB3: =$CZ3-IF($CE3>0,1,0) | DC3: =IF(OR($B3=0,C3=""),0,0+1) | DD3: =IF(OR($B3=0,D3=""),0,0+1) | DE3: =IF(OR($B3=0,E3=""),0,0+1) | DF3: =IF(OR($B3=0,F3=""),0,0+1) | DG3: =IF(OR($B3=0,G3=""),0,0+1) | DH3: =IF(OR($B3=0,H3=""),0,0+1) | DI3: =IF(OR($B3=0,I3=""),0,0+1) | DJ3: =IF(OR($B3=0,J3=""),0,0+1) | ... DV3: =IF(OR($B3=0,V3=""),0,0+1) | DW3: ='ตารางเวร'!C$7 | DX3: =IF($B3=0,0,IF(WEEKDAY('ตารางเวร'!C$6,2)=IFERROR(MATCH('ตารางเวร'!$AM$11,'ตารางเวร'!$AO$10:$AO$17,0),0),1,0))
A4: 2 | B4: =IF(2>DAY(EOMONTH(DATE('ตารางเวร'!$B$3-543,'ตารางเวร'!$B$2,1),0)),0,1) | C4: =IF($B4=0,"",IFERROR(TRIM(INDEX('ตารางเวร'!$C$10:$AG$29,1,$A4)),"")) | D4: =IF($B4=0,"",IFERROR(TRIM(INDEX('ตารางเวร'!$C$10:$AG$29,2,$A4)),"")) | E4: =IF($B4=0,"",IFERROR(TRIM(INDEX('ตารางเวร'!$C$10:$AG$29,3,$A4)),"")) | F4: =IF($B4=0,"",IFERROR(TRIM(INDEX('ตารางเวร'!$C$10:$AG$29,4,$A4)),"")) | G4: =IF($B4=0,"",IFERROR(TRIM(INDEX('ตารางเวร'!$C$10:$AG$29,5,$A4)),"")) | H4: =IF($B4=0,"",IFERROR(TRIM(INDEX('ตารางเวร'!$C$10:$AG$29,6,$A4)),"")) | I4: =IF($B4=0,"",IFERROR(TRIM(INDEX('ตารางเวร'!$C$10:$AG$29,7,$A4)),"")) | J4: =IF($B4=0,"",IFERROR(TRIM(INDEX('ตารางเวร'!$C$10:$AG$29,8,$A4)),"")) | K4: =IF($B4=0,"",IFERROR(TRIM(INDEX('ตารางเวร'!$C$10:$AG$29,9,$A4)),"")) | L4: =IF($B4=0,"",IFERROR(TRIM(INDEX('ตารางเวร'!$C$10:$AG$29,10,$A4)),"")) | M4: =IF($B4=0,"",IFERROR(TRIM(INDEX('ตารางเวร'!$C$10:$AG$29,11,$A4)),"")) | N4: =IF($B4=0,"",IFERROR(TRIM(INDEX('ตารางเวร'!$C$10:$AG$29,12,$A4)),"")) | O4: =IF($B4=0,"",IFERROR(TRIM(INDEX('ตารางเวร'!$C$10:$AG$29,13,$A4)),"")) | P4: =IF($B4=0,"",IFERROR(TRIM(INDEX('ตารางเวร'!$C$10:$AG$29,14,$A4)),"")) | Q4: =IF($B4=0,"",IFERROR(TRIM(INDEX('ตารางเวร'!$C$10:$AG$29,15,$A4)),"")) | R4: =IF($B4=0,"",IFERROR(TRIM(INDEX('ตารางเวร'!$C$10:$AG$29,16,$A4)),"")) | S4: =IF($B4=0,"",IFERROR(TRIM(INDEX('ตารางเวร'!$C$10:$AG$29,17,$A4)),"")) | T4: =IF($B4=0,"",IFERROR(TRIM(INDEX('ตารางเวร'!$C$10:$AG$29,18,$A4)),"")) | U4: =IF($B4=0,"",IFERROR(TRIM(INDEX('ตารางเวร'!$C$10:$AG$29,19,$A4)),"")) | V4: =IF($B4=0,"",IFERROR(TRIM(INDEX('ตารางเวร'!$C$10:$AG$29,20,$A4)),"")) | W4: =IF(AND($B4=1,C4<>"",ISNUMBER(FIND("*",C4))),MOD((MOD('ตารางเวร'!$B$4,9973)*7919+$A4*40289)*(1*104729+7919),99991)*100+1,999999999) | X4: =IF(AND($B4=1,D4<>"",ISNUMBER(FIND("*",D4))),MOD((MOD('ตารางเวร'!$B$4,9973)*7919+$A4*40289)*(2*104729+7919),99991)*100+2,999999999) | Y4: =IF(AND($B4=1,E4<>"",ISNUMBER(FIND("*",E4))),MOD((MOD('ตารางเวร'!$B$4,9973)*7919+$A4*40289)*(3*104729+7919),99991)*100+3,999999999) | Z4: =IF(AND($B4=1,F4<>"",ISNUMBER(FIND("*",F4))),MOD((MOD('ตารางเวร'!$B$4,9973)*7919+$A4*40289)*(4*104729+7919),99991)*100+4,999999999) | AA4: =IF(AND($B4=1,G4<>"",ISNUMBER(FIND("*",G4))),MOD((MOD('ตารางเวร'!$B$4,9973)*7919+$A4*40289)*(5*104729+7919),99991)*100+5,999999999) | AB4: =IF(AND($B4=1,H4<>"",ISNUMBER(FIND("*",H4))),MOD((MOD('ตารางเวร'!$B$4,9973)*7919+$A4*40289)*(6*104729+7919),99991)*100+6,999999999) | AC4: =IF(AND($B4=1,I4<>"",ISNUMBER(FIND("*",I4))),MOD((MOD('ตารางเวร'!$B$4,9973)*7919+$A4*40289)*(7*104729+7919),99991)*100+7,999999999) | AD4: =IF(AND($B4=1,J4<>"",ISNUMBER(FIND("*",J4))),MOD((MOD('ตารางเวร'!$B$4,9973)*7919+$A4*40289)*(8*104729+7919),99991)*100+8,999999999) | AE4: =IF(AND($B4=1,K4<>"",ISNUMBER(FIND("*",K4))),MOD((MOD('ตารางเวร'!$B$4,9973)*7919+$A4*40289)*(9*104729+7919),99991)*100+9,999999999) | AF4: =IF(AND($B4=1,L4<>"",ISNUMBER(FIND("*",L4))),MOD((MOD('ตารางเวร'!$B$4,9973)*7919+$A4*40289)*(10*104729+7919),99991)*100+10,999999999) | AG4: =IF(AND($B4=1,M4<>"",ISNUMBER(FIND("*",M4))),MOD((MOD('ตารางเวร'!$B$4,9973)*7919+$A4*40289)*(11*104729+7919),99991)*100+11,999999999) | AH4: =IF(AND($B4=1,N4<>"",ISNUMBER(FIND("*",N4))),MOD((MOD('ตารางเวร'!$B$4,9973)*7919+$A4*40289)*(12*104729+7919),99991)*100+12,999999999) | AI4: =IF(AND($B4=1,O4<>"",ISNUMBER(FIND("*",O4))),MOD((MOD('ตารางเวร'!$B$4,9973)*7919+$A4*40289)*(13*104729+7919),99991)*100+13,999999999) | AJ4: =IF(AND($B4=1,P4<>"",ISNUMBER(FIND("*",P4))),MOD((MOD('ตารางเวร'!$B$4,9973)*7919+$A4*40289)*(14*104729+7919),99991)*100+14,999999999) | AK4: =IF(AND($B4=1,Q4<>"",ISNUMBER(FIND("*",Q4))),MOD((MOD('ตารางเวร'!$B$4,9973)*7919+$A4*40289)*(15*104729+7919),99991)*100+15,999999999) | AL4: =IF(AND($B4=1,R4<>"",ISNUMBER(FIND("*",R4))),MOD((MOD('ตารางเวร'!$B$4,9973)*7919+$A4*40289)*(16*104729+7919),99991)*100+16,999999999) | AM4: =IF(AND($B4=1,S4<>"",ISNUMBER(FIND("*",S4))),MOD((MOD('ตารางเวร'!$B$4,9973)*7919+$A4*40289)*(17*104729+7919),99991)*100+17,999999999) | AN4: =IF(AND($B4=1,T4<>"",ISNUMBER(FIND("*",T4))),MOD((MOD('ตารางเวร'!$B$4,9973)*7919+$A4*40289)*(18*104729+7919),99991)*100+18,999999999) | AO4: =IF(AND($B4=1,U4<>"",ISNUMBER(FIND("*",U4))),MOD((MOD('ตารางเวร'!$B$4,9973)*7919+$A4*40289)*(19*104729+7919),99991)*100+19,999999999) | AP4: =IF(AND($B4=1,V4<>"",ISNUMBER(FIND("*",V4))),MOD((MOD('ตารางเวร'!$B$4,9973)*7919+$A4*40289)*(20*104729+7919),99991)*100+20,999999999) | AQ4: =IF(TRIM('ตารางเวร'!$B$10)<>"",999999999,W4) | AR4: =IF(TRIM('ตารางเวร'!$B$11)<>"",999999999,X4) | AS4: =IF(TRIM('ตารางเวร'!$B$12)<>"",999999999,Y4) | AT4: =IF(TRIM('ตารางเวร'!$B$13)<>"",999999999,Z4) | AU4: =IF(TRIM('ตารางเวร'!$B$14)<>"",999999999,AA4) | AV4: =IF(TRIM('ตารางเวร'!$B$15)<>"",999999999,AB4) | AW4: =IF(TRIM('ตารางเวร'!$B$16)<>"",999999999,AC4) | AX4: =IF(TRIM('ตารางเวร'!$B$17)<>"",999999999,AD4) | AY4: =IF(TRIM('ตารางเวร'!$B$18)<>"",999999999,AE4) | AZ4: =IF(TRIM('ตารางเวร'!$B$19)<>"",999999999,AF4) | BA4: =IF(TRIM('ตารางเวร'!$B$20)<>"",999999999,AG4) | BB4: =IF(TRIM('ตารางเวร'!$B$21)<>"",999999999,AH4) | BC4: =IF(TRIM('ตารางเวร'!$B$22)<>"",999999999,AI4) | BD4: =IF(TRIM('ตารางเวร'!$B$23)<>"",999999999,AJ4) | BE4: =IF(TRIM('ตารางเวร'!$B$24)<>"",999999999,AK4) | BF4: =IF(TRIM('ตารางเวร'!$B$25)<>"",999999999,AL4) | BG4: =IF(TRIM('ตารางเวร'!$B$26)<>"",999999999,AM4) | BH4: =IF(TRIM('ตารางเวร'!$B$27)<>"",999999999,AN4) | BI4: =IF(TRIM('ตารางเวร'!$B$28)<>"",999999999,AO4) | BJ4: =IF(TRIM('ตารางเวร'!$B$29)<>"",999999999,AP4) | BK4: =IF(AND($B4=1,C4<>"",NOT(ISNUMBER(FIND("*",C4)))),1,999999) | BL4: =IF(AND($B4=1,D4<>"",NOT(ISNUMBER(FIND("*",D4)))),2,999999) | BM4: =IF(AND($B4=1,E4<>"",NOT(ISNUMBER(FIND("*",E4)))),3,999999) | BN4: =IF(AND($B4=1,F4<>"",NOT(ISNUMBER(FIND("*",F4)))),4,999999) | BO4: =IF(AND($B4=1,G4<>"",NOT(ISNUMBER(FIND("*",G4)))),5,999999) | BP4: =IF(AND($B4=1,H4<>"",NOT(ISNUMBER(FIND("*",H4)))),6,999999) | BQ4: =IF(AND($B4=1,I4<>"",NOT(ISNUMBER(FIND("*",I4)))),7,999999) | BR4: =IF(AND($B4=1,J4<>"",NOT(ISNUMBER(FIND("*",J4)))),8,999999) | BS4: =IF(AND($B4=1,K4<>"",NOT(ISNUMBER(FIND("*",K4)))),9,999999) | BT4: =IF(AND($B4=1,L4<>"",NOT(ISNUMBER(FIND("*",L4)))),10,999999) | BU4: =IF(AND($B4=1,M4<>"",NOT(ISNUMBER(FIND("*",M4)))),11,999999) | BV4: =IF(AND($B4=1,N4<>"",NOT(ISNUMBER(FIND("*",N4)))),12,999999) | BW4: =IF(AND($B4=1,O4<>"",NOT(ISNUMBER(FIND("*",O4)))),13,999999) | BX4: =IF(AND($B4=1,P4<>"",NOT(ISNUMBER(FIND("*",P4)))),14,999999) | BY4: =IF(AND($B4=1,Q4<>"",NOT(ISNUMBER(FIND("*",Q4)))),15,999999) | BZ4: =IF(AND($B4=1,R4<>"",NOT(ISNUMBER(FIND("*",R4)))),16,999999) | CA4: =IF(AND($B4=1,S4<>"",NOT(ISNUMBER(FIND("*",S4)))),17,999999) | CB4: =IF(AND($B4=1,T4<>"",NOT(ISNUMBER(FIND("*",T4)))),18,999999) | CC4: =IF(AND($B4=1,U4<>"",NOT(ISNUMBER(FIND("*",U4)))),19,999999) | CD4: =IF(AND($B4=1,V4<>"",NOT(ISNUMBER(FIND("*",V4)))),20,999999) | CE4: =IF(MIN(AQ4:BJ4)>=999999999,0,MATCH(MIN(AQ4:BJ4),AQ4:BJ4,0)) | CF4: =IF($CE4=1,999999999,W4) | CG4: =IF($CE4=2,999999999,X4) | CH4: =IF($CE4=3,999999999,Y4) | CI4: =IF($CE4=4,999999999,Z4) | CJ4: =IF($CE4=5,999999999,AA4) | CK4: =IF($CE4=6,999999999,AB4) | CL4: =IF($CE4=7,999999999,AC4) | CM4: =IF($CE4=8,999999999,AD4) | CN4: =IF($CE4=9,999999999,AE4) | CO4: =IF($CE4=10,999999999,AF4) | CP4: =IF($CE4=11,999999999,AG4) | CQ4: =IF($CE4=12,999999999,AH4) | CR4: =IF($CE4=13,999999999,AI4) | CS4: =IF($CE4=14,999999999,AJ4) | CT4: =IF($CE4=15,999999999,AK4) | CU4: =IF($CE4=16,999999999,AL4) | CV4: =IF($CE4=17,999999999,AM4) | CW4: =IF($CE4=18,999999999,AN4) | CX4: =IF($CE4=19,999999999,AO4) | CY4: =IF($CE4=20,999999999,AP4) | CZ4: =COUNTIF(W4:AP4,"<999999999") | DA4: =COUNTIF(BK4:CD4,"<999999") | DB4: =$CZ4-IF($CE4>0,1,0) | DC4: =IF(OR($B4=0,C4=""),0,DC3+1) | DD4: =IF(OR($B4=0,D4=""),0,DD3+1) | DE4: =IF(OR($B4=0,E4=""),0,DE3+1) | DF4: =IF(OR($B4=0,F4=""),0,DF3+1) | DG4: =IF(OR($B4=0,G4=""),0,DG3+1) | DH4: =IF(OR($B4=0,H4=""),0,DH3+1) | DI4: =IF(OR($B4=0,I4=""),0,DI3+1) | DJ4: =IF(OR($B4=0,J4=""),0,DJ3+1) | ... DV4: =IF(OR($B4=0,V4=""),0,DV3+1) | DW4: ='ตารางเวร'!D$7 | DX4: =IF($B4=0,0,IF(WEEKDAY('ตารางเวร'!D$6,2)=IFERROR(MATCH('ตารางเวร'!$AM$11,'ตารางเวร'!$AO$10:$AO$17,0),0),1,0))
A5: 3 | B5: =IF(3>DAY(EOMONTH(DATE('ตารางเวร'!$B$3-543,'ตารางเวร'!$B$2,1),0)),0,1) | C5: =IF($B5=0,"",IFERROR(TRIM(INDEX('ตารางเวร'!$C$10:$AG$29,1,$A5)),"")) | D5: =IF($B5=0,"",IFERROR(TRIM(INDEX('ตารางเวร'!$C$10:$AG$29,2,$A5)),"")) | E5: =IF($B5=0,"",IFERROR(TRIM(INDEX('ตารางเวร'!$C$10:$AG$29,3,$A5)),"")) | F5: =IF($B5=0,"",IFERROR(TRIM(INDEX('ตารางเวร'!$C$10:$AG$29,4,$A5)),"")) | G5: =IF($B5=0,"",IFERROR(TRIM(INDEX('ตารางเวร'!$C$10:$AG$29,5,$A5)),"")) | H5: =IF($B5=0,"",IFERROR(TRIM(INDEX('ตารางเวร'!$C$10:$AG$29,6,$A5)),"")) | I5: =IF($B5=0,"",IFERROR(TRIM(INDEX('ตารางเวร'!$C$10:$AG$29,7,$A5)),"")) | J5: =IF($B5=0,"",IFERROR(TRIM(INDEX('ตารางเวร'!$C$10:$AG$29,8,$A5)),"")) | K5: =IF($B5=0,"",IFERROR(TRIM(INDEX('ตารางเวร'!$C$10:$AG$29,9,$A5)),"")) | L5: =IF($B5=0,"",IFERROR(TRIM(INDEX('ตารางเวร'!$C$10:$AG$29,10,$A5)),"")) | M5: =IF($B5=0,"",IFERROR(TRIM(INDEX('ตารางเวร'!$C$10:$AG$29,11,$A5)),"")) | N5: =IF($B5=0,"",IFERROR(TRIM(INDEX('ตารางเวร'!$C$10:$AG$29,12,$A5)),"")) | O5: =IF($B5=0,"",IFERROR(TRIM(INDEX('ตารางเวร'!$C$10:$AG$29,13,$A5)),"")) | P5: =IF($B5=0,"",IFERROR(TRIM(INDEX('ตารางเวร'!$C$10:$AG$29,14,$A5)),"")) | Q5: =IF($B5=0,"",IFERROR(TRIM(INDEX('ตารางเวร'!$C$10:$AG$29,15,$A5)),"")) | R5: =IF($B5=0,"",IFERROR(TRIM(INDEX('ตารางเวร'!$C$10:$AG$29,16,$A5)),"")) | S5: =IF($B5=0,"",IFERROR(TRIM(INDEX('ตารางเวร'!$C$10:$AG$29,17,$A5)),"")) | T5: =IF($B5=0,"",IFERROR(TRIM(INDEX('ตารางเวร'!$C$10:$AG$29,18,$A5)),"")) | U5: =IF($B5=0,"",IFERROR(TRIM(INDEX('ตารางเวร'!$C$10:$AG$29,19,$A5)),"")) | V5: =IF($B5=0,"",IFERROR(TRIM(INDEX('ตารางเวร'!$C$10:$AG$29,20,$A5)),"")) | W5: =IF(AND($B5=1,C5<>"",ISNUMBER(FIND("*",C5))),MOD((MOD('ตารางเวร'!$B$4,9973)*7919+$A5*40289)*(1*104729+7919),99991)*100+1,999999999) | X5: =IF(AND($B5=1,D5<>"",ISNUMBER(FIND("*",D5))),MOD((MOD('ตารางเวร'!$B$4,9973)*7919+$A5*40289)*(2*104729+7919),99991)*100+2,999999999) | Y5: =IF(AND($B5=1,E5<>"",ISNUMBER(FIND("*",E5))),MOD((MOD('ตารางเวร'!$B$4,9973)*7919+$A5*40289)*(3*104729+7919),99991)*100+3,999999999) | Z5: =IF(AND($B5=1,F5<>"",ISNUMBER(FIND("*",F5))),MOD((MOD('ตารางเวร'!$B$4,9973)*7919+$A5*40289)*(4*104729+7919),99991)*100+4,999999999) | AA5: =IF(AND($B5=1,G5<>"",ISNUMBER(FIND("*",G5))),MOD((MOD('ตารางเวร'!$B$4,9973)*7919+$A5*40289)*(5*104729+7919),99991)*100+5,999999999) | AB5: =IF(AND($B5=1,H5<>"",ISNUMBER(FIND("*",H5))),MOD((MOD('ตารางเวร'!$B$4,9973)*7919+$A5*40289)*(6*104729+7919),99991)*100+6,999999999) | AC5: =IF(AND($B5=1,I5<>"",ISNUMBER(FIND("*",I5))),MOD((MOD('ตารางเวร'!$B$4,9973)*7919+$A5*40289)*(7*104729+7919),99991)*100+7,999999999) | AD5: =IF(AND($B5=1,J5<>"",ISNUMBER(FIND("*",J5))),MOD((MOD('ตารางเวร'!$B$4,9973)*7919+$A5*40289)*(8*104729+7919),99991)*100+8,999999999) | AE5: =IF(AND($B5=1,K5<>"",ISNUMBER(FIND("*",K5))),MOD((MOD('ตารางเวร'!$B$4,9973)*7919+$A5*40289)*(9*104729+7919),99991)*100+9,999999999) | AF5: =IF(AND($B5=1,L5<>"",ISNUMBER(FIND("*",L5))),MOD((MOD('ตารางเวร'!$B$4,9973)*7919+$A5*40289)*(10*104729+7919),99991)*100+10,999999999) | AG5: =IF(AND($B5=1,M5<>"",ISNUMBER(FIND("*",M5))),MOD((MOD('ตารางเวร'!$B$4,9973)*7919+$A5*40289)*(11*104729+7919),99991)*100+11,999999999) | AH5: =IF(AND($B5=1,N5<>"",ISNUMBER(FIND("*",N5))),MOD((MOD('ตารางเวร'!$B$4,9973)*7919+$A5*40289)*(12*104729+7919),99991)*100+12,999999999) | AI5: =IF(AND($B5=1,O5<>"",ISNUMBER(FIND("*",O5))),MOD((MOD('ตารางเวร'!$B$4,9973)*7919+$A5*40289)*(13*104729+7919),99991)*100+13,999999999) | AJ5: =IF(AND($B5=1,P5<>"",ISNUMBER(FIND("*",P5))),MOD((MOD('ตารางเวร'!$B$4,9973)*7919+$A5*40289)*(14*104729+7919),99991)*100+14,999999999) | AK5: =IF(AND($B5=1,Q5<>"",ISNUMBER(FIND("*",Q5))),MOD((MOD('ตารางเวร'!$B$4,9973)*7919+$A5*40289)*(15*104729+7919),99991)*100+15,999999999) | AL5: =IF(AND($B5=1,R5<>"",ISNUMBER(FIND("*",R5))),MOD((MOD('ตารางเวร'!$B$4,9973)*7919+$A5*40289)*(16*104729+7919),99991)*100+16,999999999) | AM5: =IF(AND($B5=1,S5<>"",ISNUMBER(FIND("*",S5))),MOD((MOD('ตารางเวร'!$B$4,9973)*7919+$A5*40289)*(17*104729+7919),99991)*100+17,999999999) | AN5: =IF(AND($B5=1,T5<>"",ISNUMBER(FIND("*",T5))),MOD((MOD('ตารางเวร'!$B$4,9973)*7919+$A5*40289)*(18*104729+7919),99991)*100+18,999999999) | AO5: =IF(AND($B5=1,U5<>"",ISNUMBER(FIND("*",U5))),MOD((MOD('ตารางเวร'!$B$4,9973)*7919+$A5*40289)*(19*104729+7919),99991)*100+19,999999999) | AP5: =IF(AND($B5=1,V5<>"",ISNUMBER(FIND("*",V5))),MOD((MOD('ตารางเวร'!$B$4,9973)*7919+$A5*40289)*(20*104729+7919),99991)*100+20,999999999) | AQ5: =IF(TRIM('ตารางเวร'!$B$10)<>"",999999999,W5) | AR5: =IF(TRIM('ตารางเวร'!$B$11)<>"",999999999,X5) | AS5: =IF(TRIM('ตารางเวร'!$B$12)<>"",999999999,Y5) | AT5: =IF(TRIM('ตารางเวร'!$B$13)<>"",999999999,Z5) | AU5: =IF(TRIM('ตารางเวร'!$B$14)<>"",999999999,AA5) | AV5: =IF(TRIM('ตารางเวร'!$B$15)<>"",999999999,AB5) | AW5: =IF(TRIM('ตารางเวร'!$B$16)<>"",999999999,AC5) | AX5: =IF(TRIM('ตารางเวร'!$B$17)<>"",999999999,AD5) | AY5: =IF(TRIM('ตารางเวร'!$B$18)<>"",999999999,AE5) | AZ5: =IF(TRIM('ตารางเวร'!$B$19)<>"",999999999,AF5) | BA5: =IF(TRIM('ตารางเวร'!$B$20)<>"",999999999,AG5) | BB5: =IF(TRIM('ตารางเวร'!$B$21)<>"",999999999,AH5) | BC5: =IF(TRIM('ตารางเวร'!$B$22)<>"",999999999,AI5) | BD5: =IF(TRIM('ตารางเวร'!$B$23)<>"",999999999,AJ5) | BE5: =IF(TRIM('ตารางเวร'!$B$24)<>"",999999999,AK5) | BF5: =IF(TRIM('ตารางเวร'!$B$25)<>"",999999999,AL5) | BG5: =IF(TRIM('ตารางเวร'!$B$26)<>"",999999999,AM5) | BH5: =IF(TRIM('ตารางเวร'!$B$27)<>"",999999999,AN5) | BI5: =IF(TRIM('ตารางเวร'!$B$28)<>"",999999999,AO5) | BJ5: =IF(TRIM('ตารางเวร'!$B$29)<>"",999999999,AP5) | BK5: =IF(AND($B5=1,C5<>"",NOT(ISNUMBER(FIND("*",C5)))),1,999999) | BL5: =IF(AND($B5=1,D5<>"",NOT(ISNUMBER(FIND("*",D5)))),2,999999) | BM5: =IF(AND($B5=1,E5<>"",NOT(ISNUMBER(FIND("*",E5)))),3,999999) | BN5: =IF(AND($B5=1,F5<>"",NOT(ISNUMBER(FIND("*",F5)))),4,999999) | BO5: =IF(AND($B5=1,G5<>"",NOT(ISNUMBER(FIND("*",G5)))),5,999999) | BP5: =IF(AND($B5=1,H5<>"",NOT(ISNUMBER(FIND("*",H5)))),6,999999) | BQ5: =IF(AND($B5=1,I5<>"",NOT(ISNUMBER(FIND("*",I5)))),7,999999) | BR5: =IF(AND($B5=1,J5<>"",NOT(ISNUMBER(FIND("*",J5)))),8,999999) | BS5: =IF(AND($B5=1,K5<>"",NOT(ISNUMBER(FIND("*",K5)))),9,999999) | BT5: =IF(AND($B5=1,L5<>"",NOT(ISNUMBER(FIND("*",L5)))),10,999999) | BU5: =IF(AND($B5=1,M5<>"",NOT(ISNUMBER(FIND("*",M5)))),11,999999) | BV5: =IF(AND($B5=1,N5<>"",NOT(ISNUMBER(FIND("*",N5)))),12,999999) | BW5: =IF(AND($B5=1,O5<>"",NOT(ISNUMBER(FIND("*",O5)))),13,999999) | BX5: =IF(AND($B5=1,P5<>"",NOT(ISNUMBER(FIND("*",P5)))),14,999999) | BY5: =IF(AND($B5=1,Q5<>"",NOT(ISNUMBER(FIND("*",Q5)))),15,999999) | BZ5: =IF(AND($B5=1,R5<>"",NOT(ISNUMBER(FIND("*",R5)))),16,999999) | CA5: =IF(AND($B5=1,S5<>"",NOT(ISNUMBER(FIND("*",S5)))),17,999999) | CB5: =IF(AND($B5=1,T5<>"",NOT(ISNUMBER(FIND("*",T5)))),18,999999) | CC5: =IF(AND($B5=1,U5<>"",NOT(ISNUMBER(FIND("*",U5)))),19,999999) | CD5: =IF(AND($B5=1,V5<>"",NOT(ISNUMBER(FIND("*",V5)))),20,999999) | CE5: =IF(MIN(AQ5:BJ5)>=999999999,0,MATCH(MIN(AQ5:BJ5),AQ5:BJ5,0)) | CF5: =IF($CE5=1,999999999,W5) | CG5: =IF($CE5=2,999999999,X5) | CH5: =IF($CE5=3,999999999,Y5) | CI5: =IF($CE5=4,999999999,Z5) | CJ5: =IF($CE5=5,999999999,AA5) | CK5: =IF($CE5=6,999999999,AB5) | CL5: =IF($CE5=7,999999999,AC5) | CM5: =IF($CE5=8,999999999,AD5) | CN5: =IF($CE5=9,999999999,AE5) | CO5: =IF($CE5=10,999999999,AF5) | CP5: =IF($CE5=11,999999999,AG5) | CQ5: =IF($CE5=12,999999999,AH5) | CR5: =IF($CE5=13,999999999,AI5) | CS5: =IF($CE5=14,999999999,AJ5) | CT5: =IF($CE5=15,999999999,AK5) | CU5: =IF($CE5=16,999999999,AL5) | CV5: =IF($CE5=17,999999999,AM5) | CW5: =IF($CE5=18,999999999,AN5) | CX5: =IF($CE5=19,999999999,AO5) | CY5: =IF($CE5=20,999999999,AP5) | CZ5: =COUNTIF(W5:AP5,"<999999999") | DA5: =COUNTIF(BK5:CD5,"<999999") | DB5: =$CZ5-IF($CE5>0,1,0) | DC5: =IF(OR($B5=0,C5=""),0,DC4+1) | DD5: =IF(OR($B5=0,D5=""),0,DD4+1) | DE5: =IF(OR($B5=0,E5=""),0,DE4+1) | DF5: =IF(OR($B5=0,F5=""),0,DF4+1) | DG5: =IF(OR($B5=0,G5=""),0,DG4+1) | DH5: =IF(OR($B5=0,H5=""),0,DH4+1) | DI5: =IF(OR($B5=0,I5=""),0,DI4+1) | DJ5: =IF(OR($B5=0,J5=""),0,DJ4+1) | ... DV5: =IF(OR($B5=0,V5=""),0,DV4+1) | DW5: ='ตารางเวร'!E$7 | DX5: =IF($B5=0,0,IF(WEEKDAY('ตารางเวร'!E$6,2)=IFERROR(MATCH('ตารางเวร'!$AM$11,'ตารางเวร'!$AO$10:$AO$17,0),0),1,0))
A6: 4 | B6: =IF(4>DAY(EOMONTH(DATE('ตารางเวร'!$B$3-543,'ตารางเวร'!$B$2,1),0)),0,1) | C6: =IF($B6=0,"",IFERROR(TRIM(INDEX('ตารางเวร'!$C$10:$AG$29,1,$A6)),"")) | D6: =IF($B6=0,"",IFERROR(TRIM(INDEX('ตารางเวร'!$C$10:$AG$29,2,$A6)),"")) | E6: =IF($B6=0,"",IFERROR(TRIM(INDEX('ตารางเวร'!$C$10:$AG$29,3,$A6)),"")) | F6: =IF($B6=0,"",IFERROR(TRIM(INDEX('ตารางเวร'!$C$10:$AG$29,4,$A6)),"")) | G6: =IF($B6=0,"",IFERROR(TRIM(INDEX('ตารางเวร'!$C$10:$AG$29,5,$A6)),"")) | H6: =IF($B6=0,"",IFERROR(TRIM(INDEX('ตารางเวร'!$C$10:$AG$29,6,$A6)),"")) | I6: =IF($B6=0,"",IFERROR(TRIM(INDEX('ตารางเวร'!$C$10:$AG$29,7,$A6)),"")) | J6: =IF($B6=0,"",IFERROR(TRIM(INDEX('ตารางเวร'!$C$10:$AG$29,8,$A6)),"")) | K6: =IF($B6=0,"",IFERROR(TRIM(INDEX('ตารางเวร'!$C$10:$AG$29,9,$A6)),"")) | L6: =IF($B6=0,"",IFERROR(TRIM(INDEX('ตารางเวร'!$C$10:$AG$29,10,$A6)),"")) | M6: =IF($B6=0,"",IFERROR(TRIM(INDEX('ตารางเวร'!$C$10:$AG$29,11,$A6)),"")) | N6: =IF($B6=0,"",IFERROR(TRIM(INDEX('ตารางเวร'!$C$10:$AG$29,12,$A6)),"")) | O6: =IF($B6=0,"",IFERROR(TRIM(INDEX('ตารางเวร'!$C$10:$AG$29,13,$A6)),"")) | P6: =IF($B6=0,"",IFERROR(TRIM(INDEX('ตารางเวร'!$C$10:$AG$29,14,$A6)),"")) | Q6: =IF($B6=0,"",IFERROR(TRIM(INDEX('ตารางเวร'!$C$10:$AG$29,15,$A6)),"")) | R6: =IF($B6=0,"",IFERROR(TRIM(INDEX('ตารางเวร'!$C$10:$AG$29,16,$A6)),"")) | S6: =IF($B6=0,"",IFERROR(TRIM(INDEX('ตารางเวร'!$C$10:$AG$29,17,$A6)),"")) | T6: =IF($B6=0,"",IFERROR(TRIM(INDEX('ตารางเวร'!$C$10:$AG$29,18,$A6)),"")) | U6: =IF($B6=0,"",IFERROR(TRIM(INDEX('ตารางเวร'!$C$10:$AG$29,19,$A6)),"")) | V6: =IF($B6=0,"",IFERROR(TRIM(INDEX('ตารางเวร'!$C$10:$AG$29,20,$A6)),"")) | W6: =IF(AND($B6=1,C6<>"",ISNUMBER(FIND("*",C6))),MOD((MOD('ตารางเวร'!$B$4,9973)*7919+$A6*40289)*(1*104729+7919),99991)*100+1,999999999) | X6: =IF(AND($B6=1,D6<>"",ISNUMBER(FIND("*",D6))),MOD((MOD('ตารางเวร'!$B$4,9973)*7919+$A6*40289)*(2*104729+7919),99991)*100+2,999999999) | Y6: =IF(AND($B6=1,E6<>"",ISNUMBER(FIND("*",E6))),MOD((MOD('ตารางเวร'!$B$4,9973)*7919+$A6*40289)*(3*104729+7919),99991)*100+3,999999999) | Z6: =IF(AND($B6=1,F6<>"",ISNUMBER(FIND("*",F6))),MOD((MOD('ตารางเวร'!$B$4,9973)*7919+$A6*40289)*(4*104729+7919),99991)*100+4,999999999) | AA6: =IF(AND($B6=1,G6<>"",ISNUMBER(FIND("*",G6))),MOD((MOD('ตารางเวร'!$B$4,9973)*7919+$A6*40289)*(5*104729+7919),99991)*100+5,999999999) | AB6: =IF(AND($B6=1,H6<>"",ISNUMBER(FIND("*",H6))),MOD((MOD('ตารางเวร'!$B$4,9973)*7919+$A6*40289)*(6*104729+7919),99991)*100+6,999999999) | AC6: =IF(AND($B6=1,I6<>"",ISNUMBER(FIND("*",I6))),MOD((MOD('ตารางเวร'!$B$4,9973)*7919+$A6*40289)*(7*104729+7919),99991)*100+7,999999999) | AD6: =IF(AND($B6=1,J6<>"",ISNUMBER(FIND("*",J6))),MOD((MOD('ตารางเวร'!$B$4,9973)*7919+$A6*40289)*(8*104729+7919),99991)*100+8,999999999) | AE6: =IF(AND($B6=1,K6<>"",ISNUMBER(FIND("*",K6))),MOD((MOD('ตารางเวร'!$B$4,9973)*7919+$A6*40289)*(9*104729+7919),99991)*100+9,999999999) | AF6: =IF(AND($B6=1,L6<>"",ISNUMBER(FIND("*",L6))),MOD((MOD('ตารางเวร'!$B$4,9973)*7919+$A6*40289)*(10*104729+7919),99991)*100+10,999999999) | AG6: =IF(AND($B6=1,M6<>"",ISNUMBER(FIND("*",M6))),MOD((MOD('ตารางเวร'!$B$4,9973)*7919+$A6*40289)*(11*104729+7919),99991)*100+11,999999999) | AH6: =IF(AND($B6=1,N6<>"",ISNUMBER(FIND("*",N6))),MOD((MOD('ตารางเวร'!$B$4,9973)*7919+$A6*40289)*(12*104729+7919),99991)*100+12,999999999) | AI6: =IF(AND($B6=1,O6<>"",ISNUMBER(FIND("*",O6))),MOD((MOD('ตารางเวร'!$B$4,9973)*7919+$A6*40289)*(13*104729+7919),99991)*100+13,999999999) | AJ6: =IF(AND($B6=1,P6<>"",ISNUMBER(FIND("*",P6))),MOD((MOD('ตารางเวร'!$B$4,9973)*7919+$A6*40289)*(14*104729+7919),99991)*100+14,999999999) | AK6: =IF(AND($B6=1,Q6<>"",ISNUMBER(FIND("*",Q6))),MOD((MOD('ตารางเวร'!$B$4,9973)*7919+$A6*40289)*(15*104729+7919),99991)*100+15,999999999) | AL6: =IF(AND($B6=1,R6<>"",ISNUMBER(FIND("*",R6))),MOD((MOD('ตารางเวร'!$B$4,9973)*7919+$A6*40289)*(16*104729+7919),99991)*100+16,999999999) | AM6: =IF(AND($B6=1,S6<>"",ISNUMBER(FIND("*",S6))),MOD((MOD('ตารางเวร'!$B$4,9973)*7919+$A6*40289)*(17*104729+7919),99991)*100+17,999999999) | AN6: =IF(AND($B6=1,T6<>"",ISNUMBER(FIND("*",T6))),MOD((MOD('ตารางเวร'!$B$4,9973)*7919+$A6*40289)*(18*104729+7919),99991)*100+18,999999999) | AO6: =IF(AND($B6=1,U6<>"",ISNUMBER(FIND("*",U6))),MOD((MOD('ตารางเวร'!$B$4,9973)*7919+$A6*40289)*(19*104729+7919),99991)*100+19,999999999) | AP6: =IF(AND($B6=1,V6<>"",ISNUMBER(FIND("*",V6))),MOD((MOD('ตารางเวร'!$B$4,9973)*7919+$A6*40289)*(20*104729+7919),99991)*100+20,999999999) | AQ6: =IF(TRIM('ตารางเวร'!$B$10)<>"",999999999,W6) | AR6: =IF(TRIM('ตารางเวร'!$B$11)<>"",999999999,X6) | AS6: =IF(TRIM('ตารางเวร'!$B$12)<>"",999999999,Y6) | AT6: =IF(TRIM('ตารางเวร'!$B$13)<>"",999999999,Z6) | AU6: =IF(TRIM('ตารางเวร'!$B$14)<>"",999999999,AA6) | AV6: =IF(TRIM('ตารางเวร'!$B$15)<>"",999999999,AB6) | AW6: =IF(TRIM('ตารางเวร'!$B$16)<>"",999999999,AC6) | AX6: =IF(TRIM('ตารางเวร'!$B$17)<>"",999999999,AD6) | AY6: =IF(TRIM('ตารางเวร'!$B$18)<>"",999999999,AE6) | AZ6: =IF(TRIM('ตารางเวร'!$B$19)<>"",999999999,AF6) | BA6: =IF(TRIM('ตารางเวร'!$B$20)<>"",999999999,AG6) | BB6: =IF(TRIM('ตารางเวร'!$B$21)<>"",999999999,AH6) | BC6: =IF(TRIM('ตารางเวร'!$B$22)<>"",999999999,AI6) | BD6: =IF(TRIM('ตารางเวร'!$B$23)<>"",999999999,AJ6) | BE6: =IF(TRIM('ตารางเวร'!$B$24)<>"",999999999,AK6) | BF6: =IF(TRIM('ตารางเวร'!$B$25)<>"",999999999,AL6) | BG6: =IF(TRIM('ตารางเวร'!$B$26)<>"",999999999,AM6) | BH6: =IF(TRIM('ตารางเวร'!$B$27)<>"",999999999,AN6) | BI6: =IF(TRIM('ตารางเวร'!$B$28)<>"",999999999,AO6) | BJ6: =IF(TRIM('ตารางเวร'!$B$29)<>"",999999999,AP6) | BK6: =IF(AND($B6=1,C6<>"",NOT(ISNUMBER(FIND("*",C6)))),1,999999) | BL6: =IF(AND($B6=1,D6<>"",NOT(ISNUMBER(FIND("*",D6)))),2,999999) | BM6: =IF(AND($B6=1,E6<>"",NOT(ISNUMBER(FIND("*",E6)))),3,999999) | BN6: =IF(AND($B6=1,F6<>"",NOT(ISNUMBER(FIND("*",F6)))),4,999999) | BO6: =IF(AND($B6=1,G6<>"",NOT(ISNUMBER(FIND("*",G6)))),5,999999) | BP6: =IF(AND($B6=1,H6<>"",NOT(ISNUMBER(FIND("*",H6)))),6,999999) | BQ6: =IF(AND($B6=1,I6<>"",NOT(ISNUMBER(FIND("*",I6)))),7,999999) | BR6: =IF(AND($B6=1,J6<>"",NOT(ISNUMBER(FIND("*",J6)))),8,999999) | BS6: =IF(AND($B6=1,K6<>"",NOT(ISNUMBER(FIND("*",K6)))),9,999999) | BT6: =IF(AND($B6=1,L6<>"",NOT(ISNUMBER(FIND("*",L6)))),10,999999) | BU6: =IF(AND($B6=1,M6<>"",NOT(ISNUMBER(FIND("*",M6)))),11,999999) | BV6: =IF(AND($B6=1,N6<>"",NOT(ISNUMBER(FIND("*",N6)))),12,999999) | BW6: =IF(AND($B6=1,O6<>"",NOT(ISNUMBER(FIND("*",O6)))),13,999999) | BX6: =IF(AND($B6=1,P6<>"",NOT(ISNUMBER(FIND("*",P6)))),14,999999) | BY6: =IF(AND($B6=1,Q6<>"",NOT(ISNUMBER(FIND("*",Q6)))),15,999999) | BZ6: =IF(AND($B6=1,R6<>"",NOT(ISNUMBER(FIND("*",R6)))),16,999999) | CA6: =IF(AND($B6=1,S6<>"",NOT(ISNUMBER(FIND("*",S6)))),17,999999) | CB6: =IF(AND($B6=1,T6<>"",NOT(ISNUMBER(FIND("*",T6)))),18,999999) | CC6: =IF(AND($B6=1,U6<>"",NOT(ISNUMBER(FIND("*",U6)))),19,999999) | CD6: =IF(AND($B6=1,V6<>"",NOT(ISNUMBER(FIND("*",V6)))),20,999999) | CE6: =IF(MIN(AQ6:BJ6)>=999999999,0,MATCH(MIN(AQ6:BJ6),AQ6:BJ6,0)) | CF6: =IF($CE6=1,999999999,W6) | CG6: =IF($CE6=2,999999999,X6) | CH6: =IF($CE6=3,999999999,Y6) | CI6: =IF($CE6=4,999999999,Z6) | CJ6: =IF($CE6=5,999999999,AA6) | CK6: =IF($CE6=6,999999999,AB6) | CL6: =IF($CE6=7,999999999,AC6) | CM6: =IF($CE6=8,999999999,AD6) | CN6: =IF($CE6=9,999999999,AE6) | CO6: =IF($CE6=10,999999999,AF6) | CP6: =IF($CE6=11,999999999,AG6) | CQ6: =IF($CE6=12,999999999,AH6) | CR6: =IF($CE6=13,999999999,AI6) | CS6: =IF($CE6=14,999999999,AJ6) | CT6: =IF($CE6=15,999999999,AK6) | CU6: =IF($CE6=16,999999999,AL6) | CV6: =IF($CE6=17,999999999,AM6) | CW6: =IF($CE6=18,999999999,AN6) | CX6: =IF($CE6=19,999999999,AO6) | CY6: =IF($CE6=20,999999999,AP6) | CZ6: =COUNTIF(W6:AP6,"<999999999") | DA6: =COUNTIF(BK6:CD6,"<999999") | DB6: =$CZ6-IF($CE6>0,1,0) | DC6: =IF(OR($B6=0,C6=""),0,DC5+1) | DD6: =IF(OR($B6=0,D6=""),0,DD5+1) | DE6: =IF(OR($B6=0,E6=""),0,DE5+1) | DF6: =IF(OR($B6=0,F6=""),0,DF5+1) | DG6: =IF(OR($B6=0,G6=""),0,DG5+1) | DH6: =IF(OR($B6=0,H6=""),0,DH5+1) | DI6: =IF(OR($B6=0,I6=""),0,DI5+1) | DJ6: =IF(OR($B6=0,J6=""),0,DJ5+1) | ... DV6: =IF(OR($B6=0,V6=""),0,DV5+1) | DW6: ='ตารางเวร'!F$7 | DX6: =IF($B6=0,0,IF(WEEKDAY('ตารางเวร'!F$6,2)=IFERROR(MATCH('ตารางเวร'!$AM$11,'ตารางเวร'!$AO$10:$AO$17,0),0),1,0))
A7: 5 | B7: =IF(5>DAY(EOMONTH(DATE('ตารางเวร'!$B$3-543,'ตารางเวร'!$B$2,1),0)),0,1) | C7: =IF($B7=0,"",IFERROR(TRIM(INDEX('ตารางเวร'!$C$10:$AG$29,1,$A7)),"")) | D7: =IF($B7=0,"",IFERROR(TRIM(INDEX('ตารางเวร'!$C$10:$AG$29,2,$A7)),"")) | E7: =IF($B7=0,"",IFERROR(TRIM(INDEX('ตารางเวร'!$C$10:$AG$29,3,$A7)),"")) | F7: =IF($B7=0,"",IFERROR(TRIM(INDEX('ตารางเวร'!$C$10:$AG$29,4,$A7)),"")) | G7: =IF($B7=0,"",IFERROR(TRIM(INDEX('ตารางเวร'!$C$10:$AG$29,5,$A7)),"")) | H7: =IF($B7=0,"",IFERROR(TRIM(INDEX('ตารางเวร'!$C$10:$AG$29,6,$A7)),"")) | I7: =IF($B7=0,"",IFERROR(TRIM(INDEX('ตารางเวร'!$C$10:$AG$29,7,$A7)),"")) | J7: =IF($B7=0,"",IFERROR(TRIM(INDEX('ตารางเวร'!$C$10:$AG$29,8,$A7)),"")) | K7: =IF($B7=0,"",IFERROR(TRIM(INDEX('ตารางเวร'!$C$10:$AG$29,9,$A7)),"")) | L7: =IF($B7=0,"",IFERROR(TRIM(INDEX('ตารางเวร'!$C$10:$AG$29,10,$A7)),"")) | M7: =IF($B7=0,"",IFERROR(TRIM(INDEX('ตารางเวร'!$C$10:$AG$29,11,$A7)),"")) | N7: =IF($B7=0,"",IFERROR(TRIM(INDEX('ตารางเวร'!$C$10:$AG$29,12,$A7)),"")) | O7: =IF($B7=0,"",IFERROR(TRIM(INDEX('ตารางเวร'!$C$10:$AG$29,13,$A7)),"")) | P7: =IF($B7=0,"",IFERROR(TRIM(INDEX('ตารางเวร'!$C$10:$AG$29,14,$A7)),"")) | Q7: =IF($B7=0,"",IFERROR(TRIM(INDEX('ตารางเวร'!$C$10:$AG$29,15,$A7)),"")) | R7: =IF($B7=0,"",IFERROR(TRIM(INDEX('ตารางเวร'!$C$10:$AG$29,16,$A7)),"")) | S7: =IF($B7=0,"",IFERROR(TRIM(INDEX('ตารางเวร'!$C$10:$AG$29,17,$A7)),"")) | T7: =IF($B7=0,"",IFERROR(TRIM(INDEX('ตารางเวร'!$C$10:$AG$29,18,$A7)),"")) | U7: =IF($B7=0,"",IFERROR(TRIM(INDEX('ตารางเวร'!$C$10:$AG$29,19,$A7)),"")) | V7: =IF($B7=0,"",IFERROR(TRIM(INDEX('ตารางเวร'!$C$10:$AG$29,20,$A7)),"")) | W7: =IF(AND($B7=1,C7<>"",ISNUMBER(FIND("*",C7))),MOD((MOD('ตารางเวร'!$B$4,9973)*7919+$A7*40289)*(1*104729+7919),99991)*100+1,999999999) | X7: =IF(AND($B7=1,D7<>"",ISNUMBER(FIND("*",D7))),MOD((MOD('ตารางเวร'!$B$4,9973)*7919+$A7*40289)*(2*104729+7919),99991)*100+2,999999999) | Y7: =IF(AND($B7=1,E7<>"",ISNUMBER(FIND("*",E7))),MOD((MOD('ตารางเวร'!$B$4,9973)*7919+$A7*40289)*(3*104729+7919),99991)*100+3,999999999) | Z7: =IF(AND($B7=1,F7<>"",ISNUMBER(FIND("*",F7))),MOD((MOD('ตารางเวร'!$B$4,9973)*7919+$A7*40289)*(4*104729+7919),99991)*100+4,999999999) | AA7: =IF(AND($B7=1,G7<>"",ISNUMBER(FIND("*",G7))),MOD((MOD('ตารางเวร'!$B$4,9973)*7919+$A7*40289)*(5*104729+7919),99991)*100+5,999999999) | AB7: =IF(AND($B7=1,H7<>"",ISNUMBER(FIND("*",H7))),MOD((MOD('ตารางเวร'!$B$4,9973)*7919+$A7*40289)*(6*104729+7919),99991)*100+6,999999999) | AC7: =IF(AND($B7=1,I7<>"",ISNUMBER(FIND("*",I7))),MOD((MOD('ตารางเวร'!$B$4,9973)*7919+$A7*40289)*(7*104729+7919),99991)*100+7,999999999) | AD7: =IF(AND($B7=1,J7<>"",ISNUMBER(FIND("*",J7))),MOD((MOD('ตารางเวร'!$B$4,9973)*7919+$A7*40289)*(8*104729+7919),99991)*100+8,999999999) | AE7: =IF(AND($B7=1,K7<>"",ISNUMBER(FIND("*",K7))),MOD((MOD('ตารางเวร'!$B$4,9973)*7919+$A7*40289)*(9*104729+7919),99991)*100+9,999999999) | AF7: =IF(AND($B7=1,L7<>"",ISNUMBER(FIND("*",L7))),MOD((MOD('ตารางเวร'!$B$4,9973)*7919+$A7*40289)*(10*104729+7919),99991)*100+10,999999999) | AG7: =IF(AND($B7=1,M7<>"",ISNUMBER(FIND("*",M7))),MOD((MOD('ตารางเวร'!$B$4,9973)*7919+$A7*40289)*(11*104729+7919),99991)*100+11,999999999) | AH7: =IF(AND($B7=1,N7<>"",ISNUMBER(FIND("*",N7))),MOD((MOD('ตารางเวร'!$B$4,9973)*7919+$A7*40289)*(12*104729+7919),99991)*100+12,999999999) | AI7: =IF(AND($B7=1,O7<>"",ISNUMBER(FIND("*",O7))),MOD((MOD('ตารางเวร'!$B$4,9973)*7919+$A7*40289)*(13*104729+7919),99991)*100+13,999999999) | AJ7: =IF(AND($B7=1,P7<>"",ISNUMBER(FIND("*",P7))),MOD((MOD('ตารางเวร'!$B$4,9973)*7919+$A7*40289)*(14*104729+7919),99991)*100+14,999999999) | AK7: =IF(AND($B7=1,Q7<>"",ISNUMBER(FIND("*",Q7))),MOD((MOD('ตารางเวร'!$B$4,9973)*7919+$A7*40289)*(15*104729+7919),99991)*100+15,999999999) | AL7: =IF(AND($B7=1,R7<>"",ISNUMBER(FIND("*",R7))),MOD((MOD('ตารางเวร'!$B$4,9973)*7919+$A7*40289)*(16*104729+7919),99991)*100+16,999999999) | AM7: =IF(AND($B7=1,S7<>"",ISNUMBER(FIND("*",S7))),MOD((MOD('ตารางเวร'!$B$4,9973)*7919+$A7*40289)*(17*104729+7919),99991)*100+17,999999999) | AN7: =IF(AND($B7=1,T7<>"",ISNUMBER(FIND("*",T7))),MOD((MOD('ตารางเวร'!$B$4,9973)*7919+$A7*40289)*(18*104729+7919),99991)*100+18,999999999) | AO7: =IF(AND($B7=1,U7<>"",ISNUMBER(FIND("*",U7))),MOD((MOD('ตารางเวร'!$B$4,9973)*7919+$A7*40289)*(19*104729+7919),99991)*100+19,999999999) | AP7: =IF(AND($B7=1,V7<>"",ISNUMBER(FIND("*",V7))),MOD((MOD('ตารางเวร'!$B$4,9973)*7919+$A7*40289)*(20*104729+7919),99991)*100+20,999999999) | AQ7: =IF(TRIM('ตารางเวร'!$B$10)<>"",999999999,W7) | AR7: =IF(TRIM('ตารางเวร'!$B$11)<>"",999999999,X7) | AS7: =IF(TRIM('ตารางเวร'!$B$12)<>"",999999999,Y7) | AT7: =IF(TRIM('ตารางเวร'!$B$13)<>"",999999999,Z7) | AU7: =IF(TRIM('ตารางเวร'!$B$14)<>"",999999999,AA7) | AV7: =IF(TRIM('ตารางเวร'!$B$15)<>"",999999999,AB7) | AW7: =IF(TRIM('ตารางเวร'!$B$16)<>"",999999999,AC7) | AX7: =IF(TRIM('ตารางเวร'!$B$17)<>"",999999999,AD7) | AY7: =IF(TRIM('ตารางเวร'!$B$18)<>"",999999999,AE7) | AZ7: =IF(TRIM('ตารางเวร'!$B$19)<>"",999999999,AF7) | BA7: =IF(TRIM('ตารางเวร'!$B$20)<>"",999999999,AG7) | BB7: =IF(TRIM('ตารางเวร'!$B$21)<>"",999999999,AH7) | BC7: =IF(TRIM('ตารางเวร'!$B$22)<>"",999999999,AI7) | BD7: =IF(TRIM('ตารางเวร'!$B$23)<>"",999999999,AJ7) | BE7: =IF(TRIM('ตารางเวร'!$B$24)<>"",999999999,AK7) | BF7: =IF(TRIM('ตารางเวร'!$B$25)<>"",999999999,AL7) | BG7: =IF(TRIM('ตารางเวร'!$B$26)<>"",999999999,AM7) | BH7: =IF(TRIM('ตารางเวร'!$B$27)<>"",999999999,AN7) | BI7: =IF(TRIM('ตารางเวร'!$B$28)<>"",999999999,AO7) | BJ7: =IF(TRIM('ตารางเวร'!$B$29)<>"",999999999,AP7) | BK7: =IF(AND($B7=1,C7<>"",NOT(ISNUMBER(FIND("*",C7)))),1,999999) | BL7: =IF(AND($B7=1,D7<>"",NOT(ISNUMBER(FIND("*",D7)))),2,999999) | BM7: =IF(AND($B7=1,E7<>"",NOT(ISNUMBER(FIND("*",E7)))),3,999999) | BN7: =IF(AND($B7=1,F7<>"",NOT(ISNUMBER(FIND("*",F7)))),4,999999) | BO7: =IF(AND($B7=1,G7<>"",NOT(ISNUMBER(FIND("*",G7)))),5,999999) | BP7: =IF(AND($B7=1,H7<>"",NOT(ISNUMBER(FIND("*",H7)))),6,999999) | BQ7: =IF(AND($B7=1,I7<>"",NOT(ISNUMBER(FIND("*",I7)))),7,999999) | BR7: =IF(AND($B7=1,J7<>"",NOT(ISNUMBER(FIND("*",J7)))),8,999999) | BS7: =IF(AND($B7=1,K7<>"",NOT(ISNUMBER(FIND("*",K7)))),9,999999) | BT7: =IF(AND($B7=1,L7<>"",NOT(ISNUMBER(FIND("*",L7)))),10,999999) | BU7: =IF(AND($B7=1,M7<>"",NOT(ISNUMBER(FIND("*",M7)))),11,999999) | BV7: =IF(AND($B7=1,N7<>"",NOT(ISNUMBER(FIND("*",N7)))),12,999999) | BW7: =IF(AND($B7=1,O7<>"",NOT(ISNUMBER(FIND("*",O7)))),13,999999) | BX7: =IF(AND($B7=1,P7<>"",NOT(ISNUMBER(FIND("*",P7)))),14,999999) | BY7: =IF(AND($B7=1,Q7<>"",NOT(ISNUMBER(FIND("*",Q7)))),15,999999) | BZ7: =IF(AND($B7=1,R7<>"",NOT(ISNUMBER(FIND("*",R7)))),16,999999) | CA7: =IF(AND($B7=1,S7<>"",NOT(ISNUMBER(FIND("*",S7)))),17,999999) | CB7: =IF(AND($B7=1,T7<>"",NOT(ISNUMBER(FIND("*",T7)))),18,999999) | CC7: =IF(AND($B7=1,U7<>"",NOT(ISNUMBER(FIND("*",U7)))),19,999999) | CD7: =IF(AND($B7=1,V7<>"",NOT(ISNUMBER(FIND("*",V7)))),20,999999) | CE7: =IF(MIN(AQ7:BJ7)>=999999999,0,MATCH(MIN(AQ7:BJ7),AQ7:BJ7,0)) | CF7: =IF($CE7=1,999999999,W7) | CG7: =IF($CE7=2,999999999,X7) | CH7: =IF($CE7=3,999999999,Y7) | CI7: =IF($CE7=4,999999999,Z7) | CJ7: =IF($CE7=5,999999999,AA7) | CK7: =IF($CE7=6,999999999,AB7) | CL7: =IF($CE7=7,999999999,AC7) | CM7: =IF($CE7=8,999999999,AD7) | CN7: =IF($CE7=9,999999999,AE7) | CO7: =IF($CE7=10,999999999,AF7) | CP7: =IF($CE7=11,999999999,AG7) | CQ7: =IF($CE7=12,999999999,AH7) | CR7: =IF($CE7=13,999999999,AI7) | CS7: =IF($CE7=14,999999999,AJ7) | CT7: =IF($CE7=15,999999999,AK7) | CU7: =IF($CE7=16,999999999,AL7) | CV7: =IF($CE7=17,999999999,AM7) | CW7: =IF($CE7=18,999999999,AN7) | CX7: =IF($CE7=19,999999999,AO7) | CY7: =IF($CE7=20,999999999,AP7) | CZ7: =COUNTIF(W7:AP7,"<999999999") | DA7: =COUNTIF(BK7:CD7,"<999999") | DB7: =$CZ7-IF($CE7>0,1,0) | DC7: =IF(OR($B7=0,C7=""),0,DC6+1) | DD7: =IF(OR($B7=0,D7=""),0,DD6+1) | DE7: =IF(OR($B7=0,E7=""),0,DE6+1) | DF7: =IF(OR($B7=0,F7=""),0,DF6+1) | DG7: =IF(OR($B7=0,G7=""),0,DG6+1) | DH7: =IF(OR($B7=0,H7=""),0,DH6+1) | DI7: =IF(OR($B7=0,I7=""),0,DI6+1) | DJ7: =IF(OR($B7=0,J7=""),0,DJ6+1) | ... DV7: =IF(OR($B7=0,V7=""),0,DV6+1) | DW7: ='ตารางเวร'!G$7 | DX7: =IF($B7=0,0,IF(WEEKDAY('ตารางเวร'!G$6,2)=IFERROR(MATCH('ตารางเวร'!$AM$11,'ตารางเวร'!$AO$10:$AO$17,0),0),1,0))
A8: 6 | B8: =IF(6>DAY(EOMONTH(DATE('ตารางเวร'!$B$3-543,'ตารางเวร'!$B$2,1),0)),0,1) | C8: =IF($B8=0,"",IFERROR(TRIM(INDEX('ตารางเวร'!$C$10:$AG$29,1,$A8)),"")) | D8: =IF($B8=0,"",IFERROR(TRIM(INDEX('ตารางเวร'!$C$10:$AG$29,2,$A8)),"")) | E8: =IF($B8=0,"",IFERROR(TRIM(INDEX('ตารางเวร'!$C$10:$AG$29,3,$A8)),"")) | F8: =IF($B8=0,"",IFERROR(TRIM(INDEX('ตารางเวร'!$C$10:$AG$29,4,$A8)),"")) | G8: =IF($B8=0,"",IFERROR(TRIM(INDEX('ตารางเวร'!$C$10:$AG$29,5,$A8)),"")) | H8: =IF($B8=0,"",IFERROR(TRIM(INDEX('ตารางเวร'!$C$10:$AG$29,6,$A8)),"")) | I8: =IF($B8=0,"",IFERROR(TRIM(INDEX('ตารางเวร'!$C$10:$AG$29,7,$A8)),"")) | J8: =IF($B8=0,"",IFERROR(TRIM(INDEX('ตารางเวร'!$C$10:$AG$29,8,$A8)),"")) | K8: =IF($B8=0,"",IFERROR(TRIM(INDEX('ตารางเวร'!$C$10:$AG$29,9,$A8)),"")) | L8: =IF($B8=0,"",IFERROR(TRIM(INDEX('ตารางเวร'!$C$10:$AG$29,10,$A8)),"")) | M8: =IF($B8=0,"",IFERROR(TRIM(INDEX('ตารางเวร'!$C$10:$AG$29,11,$A8)),"")) | N8: =IF($B8=0,"",IFERROR(TRIM(INDEX('ตารางเวร'!$C$10:$AG$29,12,$A8)),"")) | O8: =IF($B8=0,"",IFERROR(TRIM(INDEX('ตารางเวร'!$C$10:$AG$29,13,$A8)),"")) | P8: =IF($B8=0,"",IFERROR(TRIM(INDEX('ตารางเวร'!$C$10:$AG$29,14,$A8)),"")) | Q8: =IF($B8=0,"",IFERROR(TRIM(INDEX('ตารางเวร'!$C$10:$AG$29,15,$A8)),"")) | R8: =IF($B8=0,"",IFERROR(TRIM(INDEX('ตารางเวร'!$C$10:$AG$29,16,$A8)),"")) | S8: =IF($B8=0,"",IFERROR(TRIM(INDEX('ตารางเวร'!$C$10:$AG$29,17,$A8)),"")) | T8: =IF($B8=0,"",IFERROR(TRIM(INDEX('ตารางเวร'!$C$10:$AG$29,18,$A8)),"")) | U8: =IF($B8=0,"",IFERROR(TRIM(INDEX('ตารางเวร'!$C$10:$AG$29,19,$A8)),"")) | V8: =IF($B8=0,"",IFERROR(TRIM(INDEX('ตารางเวร'!$C$10:$AG$29,20,$A8)),"")) | W8: =IF(AND($B8=1,C8<>"",ISNUMBER(FIND("*",C8))),MOD((MOD('ตารางเวร'!$B$4,9973)*7919+$A8*40289)*(1*104729+7919),99991)*100+1,999999999) | X8: =IF(AND($B8=1,D8<>"",ISNUMBER(FIND("*",D8))),MOD((MOD('ตารางเวร'!$B$4,9973)*7919+$A8*40289)*(2*104729+7919),99991)*100+2,999999999) | Y8: =IF(AND($B8=1,E8<>"",ISNUMBER(FIND("*",E8))),MOD((MOD('ตารางเวร'!$B$4,9973)*7919+$A8*40289)*(3*104729+7919),99991)*100+3,999999999) | Z8: =IF(AND($B8=1,F8<>"",ISNUMBER(FIND("*",F8))),MOD((MOD('ตารางเวร'!$B$4,9973)*7919+$A8*40289)*(4*104729+7919),99991)*100+4,999999999) | AA8: =IF(AND($B8=1,G8<>"",ISNUMBER(FIND("*",G8))),MOD((MOD('ตารางเวร'!$B$4,9973)*7919+$A8*40289)*(5*104729+7919),99991)*100+5,999999999) | AB8: =IF(AND($B8=1,H8<>"",ISNUMBER(FIND("*",H8))),MOD((MOD('ตารางเวร'!$B$4,9973)*7919+$A8*40289)*(6*104729+7919),99991)*100+6,999999999) | AC8: =IF(AND($B8=1,I8<>"",ISNUMBER(FIND("*",I8))),MOD((MOD('ตารางเวร'!$B$4,9973)*7919+$A8*40289)*(7*104729+7919),99991)*100+7,999999999) | AD8: =IF(AND($B8=1,J8<>"",ISNUMBER(FIND("*",J8))),MOD((MOD('ตารางเวร'!$B$4,9973)*7919+$A8*40289)*(8*104729+7919),99991)*100+8,999999999) | AE8: =IF(AND($B8=1,K8<>"",ISNUMBER(FIND("*",K8))),MOD((MOD('ตารางเวร'!$B$4,9973)*7919+$A8*40289)*(9*104729+7919),99991)*100+9,999999999) | AF8: =IF(AND($B8=1,L8<>"",ISNUMBER(FIND("*",L8))),MOD((MOD('ตารางเวร'!$B$4,9973)*7919+$A8*40289)*(10*104729+7919),99991)*100+10,999999999) | AG8: =IF(AND($B8=1,M8<>"",ISNUMBER(FIND("*",M8))),MOD((MOD('ตารางเวร'!$B$4,9973)*7919+$A8*40289)*(11*104729+7919),99991)*100+11,999999999) | AH8: =IF(AND($B8=1,N8<>"",ISNUMBER(FIND("*",N8))),MOD((MOD('ตารางเวร'!$B$4,9973)*7919+$A8*40289)*(12*104729+7919),99991)*100+12,999999999) | AI8: =IF(AND($B8=1,O8<>"",ISNUMBER(FIND("*",O8))),MOD((MOD('ตารางเวร'!$B$4,9973)*7919+$A8*40289)*(13*104729+7919),99991)*100+13,999999999) | AJ8: =IF(AND($B8=1,P8<>"",ISNUMBER(FIND("*",P8))),MOD((MOD('ตารางเวร'!$B$4,9973)*7919+$A8*40289)*(14*104729+7919),99991)*100+14,999999999) | AK8: =IF(AND($B8=1,Q8<>"",ISNUMBER(FIND("*",Q8))),MOD((MOD('ตารางเวร'!$B$4,9973)*7919+$A8*40289)*(15*104729+7919),99991)*100+15,999999999) | AL8: =IF(AND($B8=1,R8<>"",ISNUMBER(FIND("*",R8))),MOD((MOD('ตารางเวร'!$B$4,9973)*7919+$A8*40289)*(16*104729+7919),99991)*100+16,999999999) | AM8: =IF(AND($B8=1,S8<>"",ISNUMBER(FIND("*",S8))),MOD((MOD('ตารางเวร'!$B$4,9973)*7919+$A8*40289)*(17*104729+7919),99991)*100+17,999999999) | AN8: =IF(AND($B8=1,T8<>"",ISNUMBER(FIND("*",T8))),MOD((MOD('ตารางเวร'!$B$4,9973)*7919+$A8*40289)*(18*104729+7919),99991)*100+18,999999999) | AO8: =IF(AND($B8=1,U8<>"",ISNUMBER(FIND("*",U8))),MOD((MOD('ตารางเวร'!$B$4,9973)*7919+$A8*40289)*(19*104729+7919),99991)*100+19,999999999) | AP8: =IF(AND($B8=1,V8<>"",ISNUMBER(FIND("*",V8))),MOD((MOD('ตารางเวร'!$B$4,9973)*7919+$A8*40289)*(20*104729+7919),99991)*100+20,999999999) | AQ8: =IF(TRIM('ตารางเวร'!$B$10)<>"",999999999,W8) | AR8: =IF(TRIM('ตารางเวร'!$B$11)<>"",999999999,X8) | AS8: =IF(TRIM('ตารางเวร'!$B$12)<>"",999999999,Y8) | AT8: =IF(TRIM('ตารางเวร'!$B$13)<>"",999999999,Z8) | AU8: =IF(TRIM('ตารางเวร'!$B$14)<>"",999999999,AA8) | AV8: =IF(TRIM('ตารางเวร'!$B$15)<>"",999999999,AB8) | AW8: =IF(TRIM('ตารางเวร'!$B$16)<>"",999999999,AC8) | AX8: =IF(TRIM('ตารางเวร'!$B$17)<>"",999999999,AD8) | AY8: =IF(TRIM('ตารางเวร'!$B$18)<>"",999999999,AE8) | AZ8: =IF(TRIM('ตารางเวร'!$B$19)<>"",999999999,AF8) | BA8: =IF(TRIM('ตารางเวร'!$B$20)<>"",999999999,AG8) | BB8: =IF(TRIM('ตารางเวร'!$B$21)<>"",999999999,AH8) | BC8: =IF(TRIM('ตารางเวร'!$B$22)<>"",999999999,AI8) | BD8: =IF(TRIM('ตารางเวร'!$B$23)<>"",999999999,AJ8) | BE8: =IF(TRIM('ตารางเวร'!$B$24)<>"",999999999,AK8) | BF8: =IF(TRIM('ตารางเวร'!$B$25)<>"",999999999,AL8) | BG8: =IF(TRIM('ตารางเวร'!$B$26)<>"",999999999,AM8) | BH8: =IF(TRIM('ตารางเวร'!$B$27)<>"",999999999,AN8) | BI8: =IF(TRIM('ตารางเวร'!$B$28)<>"",999999999,AO8) | BJ8: =IF(TRIM('ตารางเวร'!$B$29)<>"",999999999,AP8) | BK8: =IF(AND($B8=1,C8<>"",NOT(ISNUMBER(FIND("*",C8)))),1,999999) | BL8: =IF(AND($B8=1,D8<>"",NOT(ISNUMBER(FIND("*",D8)))),2,999999) | BM8: =IF(AND($B8=1,E8<>"",NOT(ISNUMBER(FIND("*",E8)))),3,999999) | BN8: =IF(AND($B8=1,F8<>"",NOT(ISNUMBER(FIND("*",F8)))),4,999999) | BO8: =IF(AND($B8=1,G8<>"",NOT(ISNUMBER(FIND("*",G8)))),5,999999) | BP8: =IF(AND($B8=1,H8<>"",NOT(ISNUMBER(FIND("*",H8)))),6,999999) | BQ8: =IF(AND($B8=1,I8<>"",NOT(ISNUMBER(FIND("*",I8)))),7,999999) | BR8: =IF(AND($B8=1,J8<>"",NOT(ISNUMBER(FIND("*",J8)))),8,999999) | BS8: =IF(AND($B8=1,K8<>"",NOT(ISNUMBER(FIND("*",K8)))),9,999999) | BT8: =IF(AND($B8=1,L8<>"",NOT(ISNUMBER(FIND("*",L8)))),10,999999) | BU8: =IF(AND($B8=1,M8<>"",NOT(ISNUMBER(FIND("*",M8)))),11,999999) | BV8: =IF(AND($B8=1,N8<>"",NOT(ISNUMBER(FIND("*",N8)))),12,999999) | BW8: =IF(AND($B8=1,O8<>"",NOT(ISNUMBER(FIND("*",O8)))),13,999999) | BX8: =IF(AND($B8=1,P8<>"",NOT(ISNUMBER(FIND("*",P8)))),14,999999) | BY8: =IF(AND($B8=1,Q8<>"",NOT(ISNUMBER(FIND("*",Q8)))),15,999999) | BZ8: =IF(AND($B8=1,R8<>"",NOT(ISNUMBER(FIND("*",R8)))),16,999999) | CA8: =IF(AND($B8=1,S8<>"",NOT(ISNUMBER(FIND("*",S8)))),17,999999) | CB8: =IF(AND($B8=1,T8<>"",NOT(ISNUMBER(FIND("*",T8)))),18,999999) | CC8: =IF(AND($B8=1,U8<>"",NOT(ISNUMBER(FIND("*",U8)))),19,999999) | CD8: =IF(AND($B8=1,V8<>"",NOT(ISNUMBER(FIND("*",V8)))),20,999999) | CE8: =IF(MIN(AQ8:BJ8)>=999999999,0,MATCH(MIN(AQ8:BJ8),AQ8:BJ8,0)) | CF8: =IF($CE8=1,999999999,W8) | CG8: =IF($CE8=2,999999999,X8) | CH8: =IF($CE8=3,999999999,Y8) | CI8: =IF($CE8=4,999999999,Z8) | CJ8: =IF($CE8=5,999999999,AA8) | CK8: =IF($CE8=6,999999999,AB8) | CL8: =IF($CE8=7,999999999,AC8) | CM8: =IF($CE8=8,999999999,AD8) | CN8: =IF($CE8=9,999999999,AE8) | CO8: =IF($CE8=10,999999999,AF8) | CP8: =IF($CE8=11,999999999,AG8) | CQ8: =IF($CE8=12,999999999,AH8) | CR8: =IF($CE8=13,999999999,AI8) | CS8: =IF($CE8=14,999999999,AJ8) | CT8: =IF($CE8=15,999999999,AK8) | CU8: =IF($CE8=16,999999999,AL8) | CV8: =IF($CE8=17,999999999,AM8) | CW8: =IF($CE8=18,999999999,AN8) | CX8: =IF($CE8=19,999999999,AO8) | CY8: =IF($CE8=20,999999999,AP8) | CZ8: =COUNTIF(W8:AP8,"<999999999") | DA8: =COUNTIF(BK8:CD8,"<999999") | DB8: =$CZ8-IF($CE8>0,1,0) | DC8: =IF(OR($B8=0,C8=""),0,DC7+1) | DD8: =IF(OR($B8=0,D8=""),0,DD7+1) | DE8: =IF(OR($B8=0,E8=""),0,DE7+1) | DF8: =IF(OR($B8=0,F8=""),0,DF7+1) | DG8: =IF(OR($B8=0,G8=""),0,DG7+1) | DH8: =IF(OR($B8=0,H8=""),0,DH7+1) | DI8: =IF(OR($B8=0,I8=""),0,DI7+1) | DJ8: =IF(OR($B8=0,J8=""),0,DJ7+1) | ... DV8: =IF(OR($B8=0,V8=""),0,DV7+1) | DW8: ='ตารางเวร'!H$7 | DX8: =IF($B8=0,0,IF(WEEKDAY('ตารางเวร'!H$6,2)=IFERROR(MATCH('ตารางเวร'!$AM$11,'ตารางเวร'!$AO$10:$AO$17,0),0),1,0))
